Workbook

Sheet Bangalore DP
C1: Demand Plan | I1: Primary Sales
B2: SKU Code | C2: 46113 | D2: 46143 | E2: 46174 | F2: 46204 | G2: 46235 | H2: 46266 | I2: 46113 | J2: 46143 | K2: 46174 | L2: 46204 | M2: 46235 | Q2: Row Labels | R2: 46113 | T2: Row Labels | U2: 46143 | W2: Row Labels | X2: 46174 | Z2: Row Labels | AA2: 46204 | AC2: Row Labels | AD2: 46235
A3: Product | C3: TOTAL (in pcs) | D3: TOTAL (in pcs) | E3: TOTAL (in pcs) | F3: TOTAL (in pcs) | G3: TOTAL (in pcs) | H3: TOTAL (in pcs) | I3: TOTAL (in pcs) | J3: TOTAL (in pcs) | K3: TOTAL (in pcs) | L3: TOTAL (in pcs) | M3: TOTAL (in pcs) | Q3: BIBMSA01 | R3: 364 | T3: ACSAPM01 | U3: 20 | W3: ACSAPM01 | X3: 20 | Z3: BIBMSA01 | AA3: 517 | AC3: BIBMSA01 | AD3: 594
A4: Compound Chocolate & Cocoa | Q4: BICCPSA01 | R4: 266 | T4: BIBMSA01 | U4: 210 | W4: BIBMSA01 | X4: 154 | Z4: BICCPSA01 | AA4: 953 | AC4: BICCPSA01 | AD4: 14
A5: The Select Aisle Dark Compound Chocolate Chips - 150g | B5: CHCCSA35 | C5: 5604.2981 | D5: 5604.2981 | E5: 9413.8885 | F5: 9526.9681 | G5: 13545.779 | H5: 13413.368 | I5: =IFERROR(VLOOKUP($B5,$Q$2:$R$81,2,FALSE),"-") -> 13920 | J5: =IFERROR(VLOOKUP($B5,$T$2:$U$81,2,FALSE),"-") -> 13680 | K5: =IFERROR(VLOOKUP($B5,$W$2:$X$81,2,FALSE),"-") -> 16712 | L5: =IFERROR(VLOOKUP($B5,$Z$2:$AA$81,2,FALSE),"-") -> 18760 | M5: =IFERROR(VLOOKUP($B5,$AC$2:$AD$81,2,FALSE),"-") -> 11001 | Q5: BICPSA01 | R5: 1226 | T5: BICCPSA01 | U5: 364 | W5: BICCPSA01 | X5: 994 | Z5: BICPSA01 | AA5: 2752 | AC5: BICPSA01 | AD5: 2682
A6: TSA Dark Compound Chocolate Chips 50g | B6: CHCCSA48 | C6: 4487.2156 | D6: 4487.2156 | E6: 22789.14 | F6: 20818.044 | G6: 24229.642 | H6: 26440.99 | I6: =IFERROR(VLOOKUP($B6,$Q$2:$R$81,2,FALSE),"-") -> 20160 | J6: =IFERROR(VLOOKUP($B6,$T$2:$U$81,2,FALSE),"-") -> 15480 | K6: =IFERROR(VLOOKUP($B6,$W$2:$X$81,2,FALSE),"-") -> 41581 | L6: =IFERROR(VLOOKUP($B6,$Z$2:$AA$81,2,FALSE),"-") -> 26653 | M6: =IFERROR(VLOOKUP($B6,$AC$2:$AD$81,2,FALSE),"-") -> 24000 | Q6: BICPSA02 | R6: 1184 | T6: BICPSA01 | U6: 1070 | W6: BICPSA01 | X6: 2596 | Z6: BICPSA02 | AA6: 3542 | AC6: BICPSA02 | AD6: 2381
A7: The Select Aisle's Dark Chocolate Chips - 250g | B7: CHCCSA47 | C7: - | D7: - | E7: - | F7: - | G7: - | H7: - | I7: =IFERROR(VLOOKUP($B7,$Q$2:$R$81,2,FALSE),"-") -> - | J7: =IFERROR(VLOOKUP($B7,$T$2:$U$81,2,FALSE),"-") -> 12 | K7: =IFERROR(VLOOKUP($B7,$W$2:$X$81,2,FALSE),"-") -> 62 | L7: =IFERROR(VLOOKUP($B7,$Z$2:$AA$81,2,FALSE),"-") -> - | M7: =IFERROR(VLOOKUP($B7,$AC$2:$AD$81,2,FALSE),"-") -> - | Q7: BIEFSA01 | R7: 3696 | T7: BICPSA02 | U7: 2158 | W7: BICPSA02 | X7: 3328 | Z7: BIEFSA01 | AA7: 20112 | AC7: BIEFSA01 | AD7: 8976
A8: The Select Aisle Milk Compound Chocolate Chips - 150g | B8: CHCCSA33 | C8: 3856.4742 | D8: 3856.4742 | E8: 6340.3978 | F8: 6112.3321 | G8: 9765.8551 | H8: 8770.9815 | I8: =IFERROR(VLOOKUP($B8,$Q$2:$R$81,2,FALSE),"-") -> 10296 | J8: =IFERROR(VLOOKUP($B8,$T$2:$U$81,2,FALSE),"-") -> 10344 | K8: =IFERROR(VLOOKUP($B8,$W$2:$X$81,2,FALSE),"-") -> 13968 | L8: =IFERROR(VLOOKUP($B8,$Z$2:$AA$81,2,FALSE),"-") -> 11928 | M8: =IFERROR(VLOOKUP($B8,$AC$2:$AD$81,2,FALSE),"-") -> 6264 | Q8: BIEFSA15 | R8: 22656 | T8: BIEFSA01 | U8: 4320 | W8: BIEFSA01 | X8: 17004 | Z8: BIEFSA15 | AA8: 37632 | AC8: BIEFSA15 | AD8: 51936
A9: TSA Milk Compound Chocolate Chips 50g | B9: CHCCSA49 | C9: 3243.6515 | D9: 3243.6515 | E9: 8379.1831 | F9: 6748.6371 | G9: 7554.4961 | H9: 8736.3372 | I9: =IFERROR(VLOOKUP($B9,$Q$2:$R$81,2,FALSE),"-") -> 10080 | J9: =IFERROR(VLOOKUP($B9,$T$2:$U$81,2,FALSE),"-") -> 8280 | K9: =IFERROR(VLOOKUP($B9,$W$2:$X$81,2,FALSE),"-") -> 18180 | L9: =IFERROR(VLOOKUP($B9,$Z$2:$AA$81,2,FALSE),"-") -> 7476 | M9: =IFERROR(VLOOKUP($B9,$AC$2:$AD$81,2,FALSE),"-") -> 7668 | Q9: BIEFSA16 | R9: 3072 | T9: BIEFSA15 | U9: 28224 | W9: BIEFSA15 | X9: 39482 | Z9: BIEFSA16 | AA9: 6880 | AC9: BIEFSA16 | AD9: 6352
A10: The Select Aisle White Compound Chocolate Chips | B10: CHCCSA34 | C10: 794.46741 | D10: 794.46741 | E10: 1861.3007 | F10: 2108.8226 | G10: 3019.5465 | H10: 2496.7106 | I10: =IFERROR(VLOOKUP($B10,$Q$2:$R$81,2,FALSE),"-") -> 1536 | J10: =IFERROR(VLOOKUP($B10,$T$2:$U$81,2,FALSE),"-") -> 2280 | K10: =IFERROR(VLOOKUP($B10,$W$2:$X$81,2,FALSE),"-") -> 4038 | L10: =IFERROR(VLOOKUP($B10,$Z$2:$AA$81,2,FALSE),"-") -> 2688 | M10: =IFERROR(VLOOKUP($B10,$AC$2:$AD$81,2,FALSE),"-") -> 816 | Q10: BIFISA03 | R10: 2128 | T10: BIEFSA16 | U10: 1856 | W10: BIEFSA16 | X10: 5088 | Z10: BIFISA03 | AA10: 7224 | AC10: BIFISA03 | AD10: 7840
A11: The Select Aisle Twin Chocolate Chips 50g | B11: CHCCSA50 | C11: 72.338784 | D11: 72.338784 | E11: 1477.2985 | F11: 1571.8891 | G11: 901.86143 | H11: 1226.8647 | I11: =IFERROR(VLOOKUP($B11,$Q$2:$R$81,2,FALSE),"-") -> 1980 | J11: =IFERROR(VLOOKUP($B11,$T$2:$U$81,2,FALSE),"-") -> 3780 | K11: =IFERROR(VLOOKUP($B11,$W$2:$X$81,2,FALSE),"-") -> 6984 | L11: =IFERROR(VLOOKUP($B11,$Z$2:$AA$81,2,FALSE),"-") -> 10171 | M11: =IFERROR(VLOOKUP($B11,$AC$2:$AD$81,2,FALSE),"-") -> 7380 | Q11: BIFISA07 | R11: 23040 | T11: BIFISA03 | U11: 1736 | W11: BIFISA03 | X11: 2856 | Z11: BIFISA07 | AA11: 69504 | AC11: BIFISA07 | AD11: 74448
A12: The Select Aisle Dark Compound Chocolate Slab 500g | B12: CHCCSSA01 | C12: 3644.7709 | D12: 3644.7709 | E12: 10488.173 | F12: 10454.246 | G12: 12853.863 | H12: 12234.331 | I12: =IFERROR(VLOOKUP($B12,$Q$2:$R$81,2,FALSE),"-") -> 7480 | J12: =IFERROR(VLOOKUP($B12,$T$2:$U$81,2,FALSE),"-") -> 7200 | K12: =IFERROR(VLOOKUP($B12,$W$2:$X$81,2,FALSE),"-") -> 16796 | L12: =IFERROR(VLOOKUP($B12,$Z$2:$AA$81,2,FALSE),"-") -> 26540 | M12: =IFERROR(VLOOKUP($B12,$AC$2:$AD$81,2,FALSE),"-") -> 19400 | Q12: BIFISA09 | R12: 6642 | T12: BIFISA07 | U12: 28224 | W12: BIFISA07 | X12: 47644 | Z12: BIFISA09 | AA12: 3565 | AC12: BIFISA09 | AD12: 2916
A13: The Select Aisle Milk Compound Chocolate Bar 500 g | B13: CHCSSA04 | C13: - | D13: - | E13: 741.22807 | F13: 977.14758 | G13: 957.39933 | H13: 1185.9118 | I13: =IFERROR(VLOOKUP($B13,$Q$2:$R$81,2,FALSE),"-") -> 20 | J13: =IFERROR(VLOOKUP($B13,$T$2:$U$81,2,FALSE),"-") -> 920 | K13: =IFERROR(VLOOKUP($B13,$W$2:$X$81,2,FALSE),"-") -> 2880 | L13: =IFERROR(VLOOKUP($B13,$Z$2:$AA$81,2,FALSE),"-") -> 3940 | M13: =IFERROR(VLOOKUP($B13,$AC$2:$AD$81,2,FALSE),"-") -> 1120 | Q13: BIFISA10 | R13: 9756 | T13: BIFISA09 | U13: 5778 | W13: BIFISA09 | X13: 5886 | Z13: BIFISA10 | AA13: 37920 | AC13: BIFISA10 | AD13: 42204
A14: The Select Aisle White Compound Chocolate Bar 500 g | B14: CHCSSA05 | C14: - | D14: - | E14: 358.97436 | F14: 1090.4884 | G14: 1257.9268 | H14: 1175.2169 | I14: =IFERROR(VLOOKUP($B14,$Q$2:$R$81,2,FALSE),"-") -> 20 | J14: =IFERROR(VLOOKUP($B14,$T$2:$U$81,2,FALSE),"-") -> 994 | K14: =IFERROR(VLOOKUP($B14,$W$2:$X$81,2,FALSE),"-") -> 3651 | L14: =IFERROR(VLOOKUP($B14,$Z$2:$AA$81,2,FALSE),"-") -> 4260 | M14: =IFERROR(VLOOKUP($B14,$AC$2:$AD$81,2,FALSE),"-") -> 1040 | Q14: BIFISA11 | R14: 2430 | T14: BIFISA10 | U14: 10584 | W14: BIFISA10 | X14: 28908 | Z14: BIFISA11 | AA14: 3757 | AC14: BIFISA11 | AD14: 2304
A15: The Select Aisle Dark Compound Chocolate Slab 150g | B15: CHCSSA02 | C15: 391.77007 | D15: 391.77007 | E15: 2732.7808 | F15: 2255.848 | G15: 2881.5323 | H15: 2011.8158 | I15: =IFERROR(VLOOKUP($B15,$Q$2:$R$81,2,FALSE),"-") -> 1140 | J15: =IFERROR(VLOOKUP($B15,$T$2:$U$81,2,FALSE),"-") -> 1860 | K15: =IFERROR(VLOOKUP($B15,$W$2:$X$81,2,FALSE),"-") -> 5640 | L15: =IFERROR(VLOOKUP($B15,$Z$2:$AA$81,2,FALSE),"-") -> 8701 | M15: =IFERROR(VLOOKUP($B15,$AC$2:$AD$81,2,FALSE),"-") -> 2940 | Q15: BIMCSA01 | R15: 1260 | T15: BIFISA11 | U15: 1890 | W15: BIFISA11 | X15: 5214 | Z15: BIFISA12 | AC15: BIFISA12 | AD15: 1920
A16: The Select Aisle Milk Compound Chocolate Slab 150g | B16: CHCSSA03 | C16: 320.92515 | D16: 320.92515 | E16: 2259.2872 | F16: 1947.7311 | G16: 1752.6657 | H16: 1167.2642 | I16: =IFERROR(VLOOKUP($B16,$Q$2:$R$81,2,FALSE),"-") -> 780 | J16: =IFERROR(VLOOKUP($B16,$T$2:$U$81,2,FALSE),"-") -> 1620 | K16: =IFERROR(VLOOKUP($B16,$W$2:$X$81,2,FALSE),"-") -> 5344 | L16: =IFERROR(VLOOKUP($B16,$Z$2:$AA$81,2,FALSE),"-") -> 5580 | M16: =IFERROR(VLOOKUP($B16,$AC$2:$AD$81,2,FALSE),"-") -> 2640 | Q16: BISWSA05 | R16: 2016 | T16: BIMCSA01 | U16: 720 | W16: BIMCSA01 | X16: 811 | Z16: BIMCSA01 | AA16: 1358 | AC16: BIMCSA01 | AD16: 790
A17: The Select Aisle Cocoa Powder 70g | B17: CHCOSA06 | C17: 2141.0187 | D17: 2141.0187 | E17: 5252.1388 | F17: 5246.7009 | G17: 5168.359 | H17: 7917.3887 | I17: =IFERROR(VLOOKUP($B17,$Q$2:$R$81,2,FALSE),"-") -> 4672 | J17: =IFERROR(VLOOKUP($B17,$T$2:$U$81,2,FALSE),"-") -> 4796 | K17: =IFERROR(VLOOKUP($B17,$W$2:$X$81,2,FALSE),"-") -> 8896 | L17: =IFERROR(VLOOKUP($B17,$Z$2:$AA$81,2,FALSE),"-") -> 11841 | M17: =IFERROR(VLOOKUP($B17,$AC$2:$AD$81,2,FALSE),"-") -> 8192 | Q17: BSFLSA03 | R17: 768 | T17: BISWSA05 | U17: 754 | W17: BISWSA05 | X17: 1930 | Z17: BISWSA05 | AA17: 2526 | AC17: BISWSA05 | AD17: 4434
A18: The Select Aisle Dutch Processed Cocoa Powder 250g | B18: CHCOSA01 | C18: 146.18364 | D18: 146.18364 | E18: 424.57848 | F18: 544.09673 | G18: 584.35861 | H18: 449.74786 | I18: =IFERROR(VLOOKUP($B18,$Q$2:$R$81,2,FALSE),"-") -> 400 | J18: =IFERROR(VLOOKUP($B18,$T$2:$U$81,2,FALSE),"-") -> 260 | K18: =IFERROR(VLOOKUP($B18,$W$2:$X$81,2,FALSE),"-") -> 1020 | L18: =IFERROR(VLOOKUP($B18,$Z$2:$AA$81,2,FALSE),"-") -> 1100 | M18: =IFERROR(VLOOKUP($B18,$AC$2:$AD$81,2,FALSE),"-") -> 340 | Q18: BSLASA04 | R18: 17184 | T18: BSFLSA03 | U18: 96 | W18: BSFLSA03 | X18: 216 | Z18: BISWSA06 | AA18: 384 | AC18: BSFLSA03 | AD18: 120
A19: The Select Aisle Drinking Chocolate 200g | B19: SAHC02 | C19: 385.8387 | D19: 385.8387 | E19: 1338.3464 | F19: 1477.0428 | G19: 1747.5281 | H19: 2356.3492 | I19: =IFERROR(VLOOKUP($B19,$Q$2:$R$81,2,FALSE),"-") -> 1664 | J19: =IFERROR(VLOOKUP($B19,$T$2:$U$81,2,FALSE),"-") -> 576 | K19: =IFERROR(VLOOKUP($B19,$W$2:$X$81,2,FALSE),"-") -> 1952 | L19: =IFERROR(VLOOKUP($B19,$Z$2:$AA$81,2,FALSE),"-") -> 3744 | M19: =IFERROR(VLOOKUP($B19,$AC$2:$AD$81,2,FALSE),"-") -> 3168 | Q19: BSLASA05 | R19: 10080 | T19: BSLASA04 | U19: 16128 | W19: BSFLSA05 | X19: 40 | Z19: BSFLSA03 | AA19: 384 | AC19: BSLASA04 | AD19: 40992
A20: Functional Ingredients | Q20: BSLASA08 | R20: 300 | T20: BSLASA05 | U20: 14688 | W20: BSLASA04 | X20: 27472 | Z20: BSLASA04 | AA20: 39360 | AC20: BSLASA05 | AD20: 21984
A21: The Select Aisle Baking Soda - 100g | B21: BSLASA04 | C21: 9944.1175 | D21: 9944.1175 | E21: 12575.869 | F21: 12045.351 | G21: 12334.977 | H21: 12443.819 | I21: =IFERROR(VLOOKUP($B21,$Q$2:$R$81,2,FALSE),"-") -> 17184 | J21: =IFERROR(VLOOKUP($B21,$T$2:$U$81,2,FALSE),"-") -> 16128 | K21: =IFERROR(VLOOKUP($B21,$W$2:$X$81,2,FALSE),"-") -> 27472 | L21: =IFERROR(VLOOKUP($B21,$Z$2:$AA$81,2,FALSE),"-") -> 39360 | M21: =IFERROR(VLOOKUP($B21,$AC$2:$AD$81,2,FALSE),"-") -> 40992 | Q21: BSLASA10 | R21: 3216 | T21: BSLASA08 | U21: 226 | W21: BSLASA05 | X21: 29424 | Z21: BSLASA05 | AA21: 27344 | AC21: BSLASA08 | AD21: 180
A22: The Select Aisle Baking Soda - 1kg | B22: BSLASA08 | C22: 150 | D22: 150 | E22: 436.54822 | F22: 485.35565 | G22: 560 | H22: 596.73025 | I22: =IFERROR(VLOOKUP($B22,$Q$2:$R$81,2,FALSE),"-") -> 300 | J22: =IFERROR(VLOOKUP($B22,$T$2:$U$81,2,FALSE),"-") -> 226 | K22: =IFERROR(VLOOKUP($B22,$W$2:$X$81,2,FALSE),"-") -> 502 | L22: =IFERROR(VLOOKUP($B22,$Z$2:$AA$81,2,FALSE),"-") -> 1249 | M22: =IFERROR(VLOOKUP($B22,$AC$2:$AD$81,2,FALSE),"-") -> 180 | Q22: CDCLSA01 | R22: 730 | T22: BSLASA10 | U22: 1512 | W22: BSLASA08 | X22: 502 | Z22: BSLASA08 | AA22: 1249 | AC22: BSLASA10 | AD22: 9120
A23: The Select Aisle Double Acting Baking Powder - 100g | B23: BSLASA05 | C23: 4456.3645 | D23: 4456.3645 | E23: 8015.7533 | F23: 8664.6678 | G23: 8469.3457 | H23: 9663.2902 | I23: =IFERROR(VLOOKUP($B23,$Q$2:$R$81,2,FALSE),"-") -> 10080 | J23: =IFERROR(VLOOKUP($B23,$T$2:$U$81,2,FALSE),"-") -> 14688 | K23: =IFERROR(VLOOKUP($B23,$W$2:$X$81,2,FALSE),"-") -> 29424 | L23: =IFERROR(VLOOKUP($B23,$Z$2:$AA$81,2,FALSE),"-") -> 27344 | M23: =IFERROR(VLOOKUP($B23,$AC$2:$AD$81,2,FALSE),"-") -> 21984 | Q23: CDCLSA02 | R23: 120 | T23: CDCLSA01 | U23: 2920 | W23: BSLASA10 | X23: 6960 | Z23: BSLASA10 | AA23: 7632 | AC23: CDCLSA01 | AD23: 5310
A24: The Select Aisle Dry Instant Yeast - 25g | B24: BIFISA07 | C24: 9973.2432 | D24: 9973.2432 | E24: 34174.049 | F24: 34211.225 | G24: 49270.832 | H24: 48920.141 | I24: =IFERROR(VLOOKUP($B24,$Q$2:$R$81,2,FALSE),"-") -> 23040 | J24: =IFERROR(VLOOKUP($B24,$T$2:$U$81,2,FALSE),"-") -> 28224 | K24: =IFERROR(VLOOKUP($B24,$W$2:$X$81,2,FALSE),"-") -> 47644 | L24: =IFERROR(VLOOKUP($B24,$Z$2:$AA$81,2,FALSE),"-") -> 69504 | M24: =IFERROR(VLOOKUP($B24,$AC$2:$AD$81,2,FALSE),"-") -> 74448 | Q24: CDCLSA04 | R24: 650 | T24: CDCLSA02 | U24: 90 | W24: CDCLSA01 | X24: 2700 | Z24: CDCLSA01 | AA24: 4490 | AC24: CDCLSA04 | AD24: 4220
A25: The Select Aisle Dry Instant Yeast - 75g | B25: BIFISA03 | C25: 848.83823 | D25: 848.83823 | E25: 2015.2565 | F25: 2158.2682 | G25: 1935.1877 | H25: 2001.1026 | I25: =IFERROR(VLOOKUP($B25,$Q$2:$R$81,2,FALSE),"-") -> 2128 | J25: =IFERROR(VLOOKUP($B25,$T$2:$U$81,2,FALSE),"-") -> 1736 | K25: =IFERROR(VLOOKUP($B25,$W$2:$X$81,2,FALSE),"-") -> 2856 | L25: =IFERROR(VLOOKUP($B25,$Z$2:$AA$81,2,FALSE),"-") -> 7224 | M25: =IFERROR(VLOOKUP($B25,$AC$2:$AD$81,2,FALSE),"-") -> 7840 | Q25: CDCLSA05 | R25: 840 | T25: CDCLSA04 | U25: 1360 | W25: CDCLSA02 | X25: 60 | Z25: CDCLSA02 | AA25: 60 | AC25: CDCLSA05 | AD25: 2330
A26: The Select Aisle Agar Agar - 20g | B26: BIFISA09 | C26: 3646.7741 | D26: 3646.7741 | E26: 5838.2938 | F26: 5662.3203 | G26: 3804.9326 | H26: 3606.7334 | I26: =IFERROR(VLOOKUP($B26,$Q$2:$R$81,2,FALSE),"-") -> 6642 | J26: =IFERROR(VLOOKUP($B26,$T$2:$U$81,2,FALSE),"-") -> 5778 | K26: =IFERROR(VLOOKUP($B26,$W$2:$X$81,2,FALSE),"-") -> 5886 | L26: =IFERROR(VLOOKUP($B26,$Z$2:$AA$81,2,FALSE),"-") -> 3565 | M26: =IFERROR(VLOOKUP($B26,$AC$2:$AD$81,2,FALSE),"-") -> 2916 | Q26: CDCLSA06 | R26: 560 | T26: CDCLSA05 | U26: 610 | W26: CDCLSA04 | X26: 2690 | Z26: CDCLSA04 | AA26: 2671 | AC26: CDCLSA06 | AD26: 120
A27: The Select Aisle Gelatin | B27: BIFISA11 | C27: 1144.6356 | D27: 1144.6356 | E27: 2830.2522 | F27: 2686.2945 | G27: 2718.0552 | H27: 2919.375 | I27: =IFERROR(VLOOKUP($B27,$Q$2:$R$81,2,FALSE),"-") -> 2430 | J27: =IFERROR(VLOOKUP($B27,$T$2:$U$81,2,FALSE),"-") -> 1890 | K27: =IFERROR(VLOOKUP($B27,$W$2:$X$81,2,FALSE),"-") -> 5214 | L27: =IFERROR(VLOOKUP($B27,$Z$2:$AA$81,2,FALSE),"-") -> 3757 | M27: =IFERROR(VLOOKUP($B27,$AC$2:$AD$81,2,FALSE),"-") -> 2304 | Q27: CDCLSA07 | R27: 60 | T27: CDCLSA06 | U27: 430 | W27: CDCLSA05 | X27: 3940 | Z27: CDCLSA05 | AA27: 2880 | AC27: CDCLSA08 | AD27: 10
A28: The Select Aisle Citric Acid | B28: BSLASA10 | C28: 1380.6884 | D28: 1380.6884 | E28: 2495.8194 | F28: 2727.0877 | G28: 2950.6053 | H28: 3252.536 | I28: =IFERROR(VLOOKUP($B28,$Q$2:$R$81,2,FALSE),"-") -> 3216 | J28: =IFERROR(VLOOKUP($B28,$T$2:$U$81,2,FALSE),"-") -> 1512 | K28: =IFERROR(VLOOKUP($B28,$W$2:$X$81,2,FALSE),"-") -> 6960 | L28: =IFERROR(VLOOKUP($B28,$Z$2:$AA$81,2,FALSE),"-") -> 7632 | M28: =IFERROR(VLOOKUP($B28,$AC$2:$AD$81,2,FALSE),"-") -> 9120 | Q28: CDCLSA08 | R28: 310 | T28: CDCLSA07 | U28: 60 | W28: CDCLSA06 | X28: 80 | Z28: CDCLSA06 | AA28: 610 | AC28: CDSPSA23 | AD28: 3000
A29: The Select Aisle Corn Flour | B29: BIFISA10 | C29: 5411.2846 | D29: 5411.2846 | E29: 18966.976 | F29: 19592.71 | G29: 18882.565 | H29: 18499.436 | I29: =IFERROR(VLOOKUP($B29,$Q$2:$R$81,2,FALSE),"-") -> 9756 | J29: =IFERROR(VLOOKUP($B29,$T$2:$U$81,2,FALSE),"-") -> 10584 | K29: =IFERROR(VLOOKUP($B29,$W$2:$X$81,2,FALSE),"-") -> 28908 | L29: =IFERROR(VLOOKUP($B29,$Z$2:$AA$81,2,FALSE),"-") -> 37920 | M29: =IFERROR(VLOOKUP($B29,$AC$2:$AD$81,2,FALSE),"-") -> 42204 | Q29: CDSPSA23 | R29: 2544 | T29: CDCLSA08 | U29: 10 | W29: CDCLSA08 | X29: 30 | Z29: CDCLSA08 | AA29: 310 | AC29: CDSPSA24 | AD29: 2016
A30: The Select Aisle Icing Sugar 300g | B30: BISWSA05 | C30: 799.12479 | D30: 799.12479 | E30: 1628.2457 | F30: 1549.2299 | G30: 1757.0257 | H30: 1182.8603 | I30: =IFERROR(VLOOKUP($B30,$Q$2:$R$81,2,FALSE),"-") -> 2016 | J30: =IFERROR(VLOOKUP($B30,$T$2:$U$81,2,FALSE),"-") -> 754 | K30: =IFERROR(VLOOKUP($B30,$W$2:$X$81,2,FALSE),"-") -> 1930 | L30: =IFERROR(VLOOKUP($B30,$Z$2:$AA$81,2,FALSE),"-") -> 2526 | M30: =IFERROR(VLOOKUP($B30,$AC$2:$AD$81,2,FALSE),"-") -> 4434 | Q30: CDSPSA24 | R30: 1488 | T30: CDSPSA05 | U30: 24 | W30: CDSPSA05 | X30: 12 | Z30: CDSPSA05 | AA30: 60 | AC30: CDSPSA40 | AD30: 3785
A31: The Select Aisle T55 Baking Flour - 453g | B31: BSFLSA03 | C31: 34.690142 | D31: 34.690142 | E31: 0 | F31: 0 | G31: 0 | H31: 0 | I31: =IFERROR(VLOOKUP($B31,$Q$2:$R$81,2,FALSE),"-") -> 768 | J31: =IFERROR(VLOOKUP($B31,$T$2:$U$81,2,FALSE),"-") -> 96 | K31: =IFERROR(VLOOKUP($B31,$W$2:$X$81,2,FALSE),"-") -> 216 | L31: =IFERROR(VLOOKUP($B31,$Z$2:$AA$81,2,FALSE),"-") -> 384 | M31: =IFERROR(VLOOKUP($B31,$AC$2:$AD$81,2,FALSE),"-") -> 120 | Q31: CDSPSA40 | R31: 720 | T31: CDSPSA23 | U31: 2136 | W31: CDSPSA23 | X31: 4704 | Z31: CDSPSA23 | AA31: 4897 | AC31: CDSPSA44 | AD31: 2976
A32: Colours & Flavours | Q32: CDSPSA44 | R32: 384 | T32: CDSPSA24 | U32: 708 | W32: CDSPSA24 | X32: 1488 | Z32: CDSPSA24 | AA32: 1825 | AC32: CDSPSA54 | AD32: 432
A33: The Select Aisle Vanilla Essence 30 ml | B33: BIEFSA15 | C33: 11517.73 | D33: 11517.73 | E33: 22918.318 | F33: 21395.988 | G33: 26042.172 | H33: 28619.179 | I33: =IFERROR(VLOOKUP($B33,$Q$2:$R$81,2,FALSE),"-") -> 22656 | J33: =IFERROR(VLOOKUP($B33,$T$2:$U$81,2,FALSE),"-") -> 28224 | K33: =IFERROR(VLOOKUP($B33,$W$2:$X$81,2,FALSE),"-") -> 39482 | L33: =IFERROR(VLOOKUP($B33,$Z$2:$AA$81,2,FALSE),"-") -> 37632 | M33: =IFERROR(VLOOKUP($B33,$AC$2:$AD$81,2,FALSE),"-") -> 51936 | Q33: CDSPSA54 | R33: 192 | T33: CDSPSA26 | U33: 24 | W33: CDSPSA26 | X33: 12 | Z33: CDSPSA26 | AA33: 108 | AC33: CDTFSA01 | AD33: 3120
A34: The Select Aisle Vanilla Flavour - 100ml | B34: BIEFSA01 | C34: 2440.2715 | D34: 2440.2715 | E34: 6143.3692 | F34: 7047.7703 | G34: 8218.8458 | H34: 7437.2974 | I34: =IFERROR(VLOOKUP($B34,$Q$2:$R$81,2,FALSE),"-") -> 3696 | J34: =IFERROR(VLOOKUP($B34,$T$2:$U$81,2,FALSE),"-") -> 4320 | K34: =IFERROR(VLOOKUP($B34,$W$2:$X$81,2,FALSE),"-") -> 17004 | L34: =IFERROR(VLOOKUP($B34,$Z$2:$AA$81,2,FALSE),"-") -> 20112 | M34: =IFERROR(VLOOKUP($B34,$AC$2:$AD$81,2,FALSE),"-") -> 8976 | Q34: CDTFSA01 | R34: 1800 | T34: CDSPSA40 | U34: 672 | W34: CDSPSA40 | X34: 1488 | Z34: CDSPSA40 | AA34: 2812 | AC34: CHCCSA33 | AD34: 6264
A35: The Select Aisle Vanilla Extract - 30ml | B35: BIEFSA16 | C35: 1377.8096 | D35: 1377.8096 | E35: 2866.7081 | F35: 3108.5656 | G35: 2982.5909 | H35: 3658.2068 | I35: =IFERROR(VLOOKUP($B35,$Q$2:$R$81,2,FALSE),"-") -> 3072 | J35: =IFERROR(VLOOKUP($B35,$T$2:$U$81,2,FALSE),"-") -> 1856 | K35: =IFERROR(VLOOKUP($B35,$W$2:$X$81,2,FALSE),"-") -> 5088 | L35: =IFERROR(VLOOKUP($B35,$Z$2:$AA$81,2,FALSE),"-") -> 6880 | M35: =IFERROR(VLOOKUP($B35,$AC$2:$AD$81,2,FALSE),"-") -> 6352 | Q35: CHCCSA33 | R35: 10296 | T35: CDSPSA44 | U35: 336 | W35: CDSPSA44 | X35: 960 | Z35: CDSPSA44 | AA35: 2016 | AC35: CHCCSA34 | AD35: 816
A36: The Select Aisle Yellow Gel Food Colour 30ml | B36: CDCLSA05 | C36: 387.52801 | D36: 387.52801 | E36: 646.9667 | F36: 647.46834 | G36: 853.52343 | H36: 669.24416 | I36: =IFERROR(VLOOKUP($B36,$Q$2:$R$81,2,FALSE),"-") -> 840 | J36: =IFERROR(VLOOKUP($B36,$T$2:$U$81,2,FALSE),"-") -> 610 | K36: =IFERROR(VLOOKUP($B36,$W$2:$X$81,2,FALSE),"-") -> 3940 | L36: =IFERROR(VLOOKUP($B36,$Z$2:$AA$81,2,FALSE),"-") -> 2880 | M36: =IFERROR(VLOOKUP($B36,$AC$2:$AD$81,2,FALSE),"-") -> 2330 | Q36: CHCCSA34 | R36: 1536 | T36: CDTFSA01 | U36: 3024 | W36: CDSPSA54 | X36: 240 | Z36: CDSPSA54 | AA36: 384 | AC36: CHCCSA35 | AD36: 11001
A37: The Select Aisle Red Gel Food Colour 30ml | B37: CDCLSA01 | C37: 479.94949 | D37: 479.94949 | E37: 833.06944 | F37: 906.46467 | G37: 1136.7974 | H37: 948.43506 | I37: =IFERROR(VLOOKUP($B37,$Q$2:$R$81,2,FALSE),"-") -> 730 | J37: =IFERROR(VLOOKUP($B37,$T$2:$U$81,2,FALSE),"-") -> 2920 | K37: =IFERROR(VLOOKUP($B37,$W$2:$X$81,2,FALSE),"-") -> 2700 | L37: =IFERROR(VLOOKUP($B37,$Z$2:$AA$81,2,FALSE),"-") -> 4490 | M37: =IFERROR(VLOOKUP($B37,$AC$2:$AD$81,2,FALSE),"-") -> 5310 | Q37: CHCCSA35 | R37: 13920 | T37: CHCCSA33 | U37: 10344 | W37: CDTFSA01 | X37: 6858 | Z37: CDTFSA01 | AA37: 4729 | AC37: CHCCSA36 | AD37: 444
A38: The Select Aisle Dark Green Gel Food Colour 30ml | B38: CDCLSA02 | C38: 0 | D38: 0 | E38: - | F38: - | G38: - | H38: - | I38: =IFERROR(VLOOKUP($B38,$Q$2:$R$81,2,FALSE),"-") -> 120 | J38: =IFERROR(VLOOKUP($B38,$T$2:$U$81,2,FALSE),"-") -> 90 | K38: =IFERROR(VLOOKUP($B38,$W$2:$X$81,2,FALSE),"-") -> 60 | L38: =IFERROR(VLOOKUP($B38,$Z$2:$AA$81,2,FALSE),"-") -> 60 | M38: =IFERROR(VLOOKUP($B38,$AC$2:$AD$81,2,FALSE),"-") -> - | Q38: CHCCSA48 | R38: 20160 | T38: CHCCSA34 | U38: 2280 | W38: CHCCSA33 | X38: 13968 | Z38: CHCCSA33 | AA38: 11928 | AC38: CHCCSA48 | AD38: 24000
A39: The Select Aisle Dark Blue Gel Food Colour 30ml | B39: CDCLSA03 | C39: 0 | D39: 0 | E39: 0 | F39: 0 | G39: 0 | H39: 0 | I39: =IFERROR(VLOOKUP($B39,$Q$2:$R$81,2,FALSE),"-") -> - | J39: =IFERROR(VLOOKUP($B39,$T$2:$U$81,2,FALSE),"-") -> - | K39: =IFERROR(VLOOKUP($B39,$W$2:$X$81,2,FALSE),"-") -> - | L39: =IFERROR(VLOOKUP($B39,$Z$2:$AA$81,2,FALSE),"-") -> - | M39: =IFERROR(VLOOKUP($B39,$AC$2:$AD$81,2,FALSE),"-") -> - | Q39: CHCCSA49 | R39: 10080 | T39: CHCCSA35 | U39: 13680 | W39: CHCCSA34 | X39: 4038 | Z39: CHCCSA34 | AA39: 2688 | AC39: CHCCSA49 | AD39: 7668
A40: The Select Aisle Sky Blue Gel Food Colour 30ml | B40: CDCLSA04 | C40: 317.7404 | D40: 317.7404 | E40: 736.74933 | F40: 829.93573 | G40: 886.0679 | H40: 776.42922 | I40: =IFERROR(VLOOKUP($B40,$Q$2:$R$81,2,FALSE),"-") -> 650 | J40: =IFERROR(VLOOKUP($B40,$T$2:$U$81,2,FALSE),"-") -> 1360 | K40: =IFERROR(VLOOKUP($B40,$W$2:$X$81,2,FALSE),"-") -> 2690 | L40: =IFERROR(VLOOKUP($B40,$Z$2:$AA$81,2,FALSE),"-") -> 2671 | M40: =IFERROR(VLOOKUP($B40,$AC$2:$AD$81,2,FALSE),"-") -> 4220 | Q40: CHCCSA50 | R40: 1980 | T40: CHCCSA40 | U40: 97 | W40: CHCCSA35 | X40: 16712 | Z40: CHCCSA35 | AA40: 18760 | AC40: CHCCSA50 | AD40: 7380
...

Sheet Hyderabad DP
C1: Demand Plan | I1: Primary Sales
B2: SKU Code | C2: 46113 | D2: 46143 | E2: 46174 | F2: 46204 | G2: 46235 | H2: 46266 | I2: 46113 | J2: 46143 | K2: 46174 | L2: 46204 | M2: 46235 | O2: SKU ID | P2: 46113 | R2: Row Labels | S2: 46143 | V2: Row Labels | W2: 46174 | Z2: Row Labels | AA2: 46204 | AC2: Row Labels | AD2: 46235
A3: Product | C3: TOTAL (in pcs) | D3: TOTAL (in pcs) | E3: TOTAL (in pcs) | F3: TOTAL (in pcs) | G3: TOTAL (in pcs) | H3: TOTAL (in pcs) | I3: TOTAL (in pcs) | J3: TOTAL (in pcs) | K3: TOTAL (in pcs) | L3: TOTAL (in pcs) | M3: TOTAL (in pcs) | O3: BIBMSA01 | P3: 80 | R3: BIBMSA01 | S3: 52 | V3: BIBMSA01 | W3: 78 | Z3: BICCPSA01 | AA3: 98 | AC3: BIBMSA01 | AD3: 26
A4: Compound Chocolate & Cocoa | O4: BICCPSA01 | P4: 84 | R4: BICCPSA01 | S4: 84 | V4: BICCPSA01 | W4: 140 | Z4: BICPSA01 | AA4: 494 | AC4: BICPSA01 | AD4: 390
A5: The Select Aisle Dark Compound Chocolate Chips - 150g | B5: CHCCSA35 | C5: 2862.5849 | D5: 2862.5849 | E5: 3685.4944 | F5: 3323.2398 | G5: 5894.1527 | H5: 4548.5054 | I5: =IFERROR(VLOOKUP($B5,$O$2:$P$55,2,FALSE),"-") -> 3096 | J5: =IFERROR(VLOOKUP($B5,$R$2:$S$65,2,FALSE),"-") -> 4536 | K5: =IFERROR(VLOOKUP($B5,$V$2:$W$65,2,FALSE),"-") -> 4536 | L5: =IFERROR(VLOOKUP($B5,$Z$2:$AA$65,2,FALSE),"-") -> 5256 | M5: =IFERROR(VLOOKUP($B5,$AC$2:$AD$65,2,FALSE),"-") -> 3300 | O5: BICPSA01 | P5: 260 | R5: BICPSA01 | S5: 312 | V5: BICPSA01 | W5: 416 | Z5: BICPSA02 | AA5: 936 | AC5: BICPSA02 | AD5: 520
A6: TSA Dark Compound Chocolate Chips 50g | B6: CHCCSA48 | C6: 3487.3107 | D6: 3487.3107 | E6: 6907.7922 | F6: 6380.0594 | G6: 6360.531 | H6: 6389.1951 | I6: =IFERROR(VLOOKUP($B6,$O$2:$P$55,2,FALSE),"-") -> 5280 | J6: =IFERROR(VLOOKUP($B6,$R$2:$S$65,2,FALSE),"-") -> 5220 | K6: =IFERROR(VLOOKUP($B6,$V$2:$W$65,2,FALSE),"-") -> 4320 | L6: =IFERROR(VLOOKUP($B6,$Z$2:$AA$65,2,FALSE),"-") -> 4320 | M6: =IFERROR(VLOOKUP($B6,$AC$2:$AD$65,2,FALSE),"-") -> 3780 | O6: BICPSA02 | P6: 130 | R6: BICPSA02 | S6: 364 | V6: BICPSA02 | W6: 650 | Z6: BIEFSA01 | AA6: 2352 | AC6: BIEFSA01 | AD6: 1536
A7: The Select Aisle's Dark Chocolate Chips - 250g | B7: CHCCSA47 | C7: - | D7: - | E7: - | F7: - | G7: - | H7: - | I7: =IFERROR(VLOOKUP($B7,$O$2:$P$55,2,FALSE),"-") -> - | J7: =IFERROR(VLOOKUP($B7,$R$2:$S$65,2,FALSE),"-") -> - | K7: =IFERROR(VLOOKUP($B7,$V$2:$W$65,2,FALSE),"-") -> - | L7: =IFERROR(VLOOKUP($B7,$Z$2:$AA$65,2,FALSE),"-") -> - | M7: =IFERROR(VLOOKUP($B7,$AC$2:$AD$65,2,FALSE),"-") -> - | O7: BIEFSA01 | P7: 336 | R7: BIEFSA01 | S7: 2112 | V7: BIEFSA01 | W7: 4560 | Z7: BIEFSA15 | AA7: 10656 | AC7: BIEFSA15 | AD7: 6144
A8: The Select Aisle Milk Compound Chocolate Chips - 150g | B8: CHCCSA33 | C8: 2354.5005 | D8: 2354.5005 | E8: 1909.3843 | F8: 2591.3838 | G8: 2766.0295 | H8: 2645.7197 | I8: =IFERROR(VLOOKUP($B8,$O$2:$P$55,2,FALSE),"-") -> 2712 | J8: =IFERROR(VLOOKUP($B8,$R$2:$S$65,2,FALSE),"-") -> 3384 | K8: =IFERROR(VLOOKUP($B8,$V$2:$W$65,2,FALSE),"-") -> 2736 | L8: =IFERROR(VLOOKUP($B8,$Z$2:$AA$65,2,FALSE),"-") -> 2952 | M8: =IFERROR(VLOOKUP($B8,$AC$2:$AD$65,2,FALSE),"-") -> 2592 | O8: BIEFSA15 | P8: 6240 | R8: BIEFSA15 | S8: 10368 | V8: BIEFSA15 | W8: 13440 | Z8: BIEFSA16 | AA8: 1040 | AC8: BIEFSA16 | AD8: 960
A9: TSA Milk Compound Chocolate Chips 50g | B9: CHCCSA49 | C9: 2537.0662 | D9: 2537.0662 | E9: 4263.5854 | F9: 3790.0095 | G9: 3031.0963 | H9: 2896.6054 | I9: =IFERROR(VLOOKUP($B9,$O$2:$P$55,2,FALSE),"-") -> 2700 | J9: =IFERROR(VLOOKUP($B9,$R$2:$S$65,2,FALSE),"-") -> 3600 | K9: =IFERROR(VLOOKUP($B9,$V$2:$W$65,2,FALSE),"-") -> 2160 | L9: =IFERROR(VLOOKUP($B9,$Z$2:$AA$65,2,FALSE),"-") -> 1800 | M9: =IFERROR(VLOOKUP($B9,$AC$2:$AD$65,2,FALSE),"-") -> 1260 | O9: BIEFSA16 | P9: 448 | R9: BIEFSA16 | S9: 1124 | V9: BIEFSA16 | W9: 1248 | Z9: BIFISA03 | AA9: 504 | AC9: BIFISA03 | AD9: 616
A10: The Select Aisle White Compound Chocolate Chips | B10: CHCCSA34 | C10: 452.89511 | D10: 452.89511 | E10: 366.05215 | F10: 466.12529 | G10: 746.82751 | H10: 634.42338 | I10: =IFERROR(VLOOKUP($B10,$O$2:$P$55,2,FALSE),"-") -> 384 | J10: =IFERROR(VLOOKUP($B10,$R$2:$S$65,2,FALSE),"-") -> 480 | K10: =IFERROR(VLOOKUP($B10,$V$2:$W$65,2,FALSE),"-") -> 480 | L10: =IFERROR(VLOOKUP($B10,$Z$2:$AA$65,2,FALSE),"-") -> 336 | M10: =IFERROR(VLOOKUP($B10,$AC$2:$AD$65,2,FALSE),"-") -> 432 | O10: BIFISA03 | P10: 280 | R10: BIFISA03 | S10: 392 | V10: BIFISA03 | W10: 336 | Z10: BIFISA07 | AA10: 13968 | AC10: BIFISA07 | AD10: 13536
A11: The Select Aisle Twin Chocolate Chips 50g | B11: CHCCSA50 | C11: 59.402962 | D11: 59.402962 | E11: 401.17465 | F11: 337.99688 | G11: 475.05458 | H11: 432.41809 | I11: =IFERROR(VLOOKUP($B11,$O$2:$P$55,2,FALSE),"-") -> 270 | J11: =IFERROR(VLOOKUP($B11,$R$2:$S$65,2,FALSE),"-") -> 990 | K11: =IFERROR(VLOOKUP($B11,$V$2:$W$65,2,FALSE),"-") -> 1260 | L11: =IFERROR(VLOOKUP($B11,$Z$2:$AA$65,2,FALSE),"-") -> 270 | M11: =IFERROR(VLOOKUP($B11,$AC$2:$AD$65,2,FALSE),"-") -> 540 | O11: BIFISA07 | P11: 4032 | R11: BIFISA07 | S11: 8496 | V11: BIFISA07 | W11: 11088 | Z11: BIFISA09 | AA11: 540 | AC11: BIFISA09 | AD11: 486
A12: The Select Aisle Dark Compound Chocolate Slab 500g | B12: CHCCSSA01 | C12: 2102.1754 | D12: 2102.1754 | E12: 3382.2936 | F12: 2961.9322 | G12: 4061.6333 | H12: 4086.4702 | I12: =IFERROR(VLOOKUP($B12,$O$2:$P$55,2,FALSE),"-") -> 1780 | J12: =IFERROR(VLOOKUP($B12,$R$2:$S$65,2,FALSE),"-") -> 2000 | K12: =IFERROR(VLOOKUP($B12,$V$2:$W$65,2,FALSE),"-") -> 3520 | L12: =IFERROR(VLOOKUP($B12,$Z$2:$AA$65,2,FALSE),"-") -> 4880 | M12: =IFERROR(VLOOKUP($B12,$AC$2:$AD$65,2,FALSE),"-") -> 3820 | O12: BIFISA09 | P12: 1674 | R12: BIFISA09 | S12: 3780 | V12: BIFISA09 | W12: 2214 | Z12: BIFISA10 | AA12: 1980 | AC12: BIFISA10 | AD12: 2484
A13: The Select Aisle Milk Compound Chocolate Bar 500 g | B13: CHCSSA04 | C13: - | D13: - | E13: 285.08772 | F13: 250.55066 | G13: 428.48641 | H13: 511.05631 | I13: =IFERROR(VLOOKUP($B13,$O$2:$P$55,2,FALSE),"-") -> 20 | J13: =IFERROR(VLOOKUP($B13,$R$2:$S$65,2,FALSE),"-") -> 740 | K13: =IFERROR(VLOOKUP($B13,$V$2:$W$65,2,FALSE),"-") -> 500 | L13: =IFERROR(VLOOKUP($B13,$Z$2:$AA$65,2,FALSE),"-") -> 184 | M13: =IFERROR(VLOOKUP($B13,$AC$2:$AD$65,2,FALSE),"-") -> 20 | O13: BIFISA10 | P13: 1080 | R13: BIFISA10 | S13: 2160 | V13: BIFISA10 | W13: 1872 | Z13: BIFISA11 | AA13: 108 | AC13: BIFISA11 | AD13: 324
A14: The Select Aisle White Compound Chocolate Bar 500 g | B14: CHCSSA05 | C14: - | D14: - | E14: 466.66667 | F14: 104.37018 | G14: 380.48402 | H14: 388.33254 | I14: =IFERROR(VLOOKUP($B14,$O$2:$P$55,2,FALSE),"-") -> 20 | J14: =IFERROR(VLOOKUP($B14,$R$2:$S$65,2,FALSE),"-") -> 419 | K14: =IFERROR(VLOOKUP($B14,$V$2:$W$65,2,FALSE),"-") -> 360 | L14: =IFERROR(VLOOKUP($B14,$Z$2:$AA$65,2,FALSE),"-") -> 424 | M14: =IFERROR(VLOOKUP($B14,$AC$2:$AD$65,2,FALSE),"-") -> 40 | O14: BIFISA11 | P14: 486 | R14: BIFISA11 | S14: 702 | V14: BIFISA11 | W14: 1026 | Z14: BIFISA12 | AC14: BIFISA12 | AD14: 160
A15: The Select Aisle Dark Compound Chocolate Slab 150g | B15: CHCSSA02 | C15: 361.8331 | D15: 361.8331 | E15: 636.03007 | F15: 516.69944 | G15: 998.69327 | H15: 585.46139 | I15: =IFERROR(VLOOKUP($B15,$O$2:$P$55,2,FALSE),"-") -> 180 | J15: =IFERROR(VLOOKUP($B15,$R$2:$S$65,2,FALSE),"-") -> 420 | K15: =IFERROR(VLOOKUP($B15,$V$2:$W$65,2,FALSE),"-") -> 960 | L15: =IFERROR(VLOOKUP($B15,$Z$2:$AA$65,2,FALSE),"-") -> 720 | M15: =IFERROR(VLOOKUP($B15,$AC$2:$AD$65,2,FALSE),"-") -> 180 | O15: BIMCSA01 | P15: 270 | R15: BIMCSA01 | S15: 360 | V15: BIMCSA01 | W15: 149 | Z15: BIMCSA01 | AA15: 237 | AC15: BIMCSA01 | AD15: 344
A16: The Select Aisle Milk Compound Chocolate Slab 150g | B16: CHCSSA03 | C16: 317.41287 | D16: 317.41287 | E16: 547.84483 | F16: 373.59684 | G16: 713.50292 | H16: 471.0598 | I16: =IFERROR(VLOOKUP($B16,$O$2:$P$55,2,FALSE),"-") -> 180 | J16: =IFERROR(VLOOKUP($B16,$R$2:$S$65,2,FALSE),"-") -> 480 | K16: =IFERROR(VLOOKUP($B16,$V$2:$W$65,2,FALSE),"-") -> 720 | L16: =IFERROR(VLOOKUP($B16,$Z$2:$AA$65,2,FALSE),"-") -> 540 | M16: =IFERROR(VLOOKUP($B16,$AC$2:$AD$65,2,FALSE),"-") -> 180 | O16: BISWSA05 | P16: 336 | R16: BISWSA05 | S16: 336 | V16: BISWSA05 | W16: 336 | Z16: BISWSA05 | AA16: 168 | AC16: BISWSA05 | AD16: 504
A17: The Select Aisle Cocoa Powder 70g | B17: CHCOSA06 | C17: 1869.9362 | D17: 1869.9362 | E17: 1683.6635 | F17: 1830.0148 | G17: 2541.8685 | H17: 2509.7998 | I17: =IFERROR(VLOOKUP($B17,$O$2:$P$55,2,FALSE),"-") -> 1536 | J17: =IFERROR(VLOOKUP($B17,$R$2:$S$65,2,FALSE),"-") -> 3136 | K17: =IFERROR(VLOOKUP($B17,$V$2:$W$65,2,FALSE),"-") -> 3200 | L17: =IFERROR(VLOOKUP($B17,$Z$2:$AA$65,2,FALSE),"-") -> 2112 | M17: =IFERROR(VLOOKUP($B17,$AC$2:$AD$65,2,FALSE),"-") -> 3264 | O17: BSFLSA03 | P17: 96 | R17: BSLASA04 | S17: 10368 | V17: BSFLSA03 | W17: 24 | Z17: BISWSA06 | AA17: 168 | AC17: BISWSA06 | AD17: 24
A18: The Select Aisle Dutch Processed Cocoa Powder 250g | B18: CHCOSA01 | C18: 39.156331 | D18: 39.156331 | E18: 210.64678 | F18: 155.76102 | G18: 110.68547 | H18: 102.51051 | I18: =IFERROR(VLOOKUP($B18,$O$2:$P$55,2,FALSE),"-") -> 80 | J18: =IFERROR(VLOOKUP($B18,$R$2:$S$65,2,FALSE),"-") -> 200 | K18: =IFERROR(VLOOKUP($B18,$V$2:$W$65,2,FALSE),"-") -> 280 | L18: =IFERROR(VLOOKUP($B18,$Z$2:$AA$65,2,FALSE),"-") -> 180 | M18: =IFERROR(VLOOKUP($B18,$AC$2:$AD$65,2,FALSE),"-") -> 300 | O18: BSLASA04 | P18: 2592 | R18: BSLASA05 | S18: 4512 | V18: BSLASA04 | W18: 5952 | Z18: BSFLSA03 | AA18: 120 | AC18: BSLASA04 | AD18: 7776
A19: The Select Aisle Drinking Chocolate 200g | B19: SAHC02 | C19: 152.61216 | D19: 152.61216 | E19: 215.7609 | F19: 284.53745 | G19: 358.90386 | H19: 515.55114 | I19: =IFERROR(VLOOKUP($B19,$O$2:$P$55,2,FALSE),"-") -> 128 | J19: =IFERROR(VLOOKUP($B19,$R$2:$S$65,2,FALSE),"-") -> 160 | K19: =IFERROR(VLOOKUP($B19,$V$2:$W$65,2,FALSE),"-") -> 544 | L19: =IFERROR(VLOOKUP($B19,$Z$2:$AA$65,2,FALSE),"-") -> 704 | M19: =IFERROR(VLOOKUP($B19,$AC$2:$AD$65,2,FALSE),"-") -> 128 | O19: BSLASA05 | P19: 1344 | R19: BSLASA10 | S19: 792 | V19: BSLASA05 | W19: 4704 | Z19: BSLASA04 | AA19: 4608 | AC19: BSLASA05 | AD19: 4896
A20: Functional Ingredients | O20: BSLASA10 | P20: 576 | R20: CDCLSA01 | S20: 200 | V20: BSLASA10 | W20: 1008 | Z20: BSLASA05 | AA20: 3840 | AC20: BSLASA10 | AD20: 816
A21: The Select Aisle Baking Soda - 100g | B21: BSLASA04 | C21: 4054.6344 | D21: 4054.6344 | E21: 4278.9155 | F21: 3624.81 | G21: 4909.5192 | H21: 4916.3905 | I21: =IFERROR(VLOOKUP($B21,$O$2:$P$55,2,FALSE),"-") -> 2592 | J21: =IFERROR(VLOOKUP($B21,$R$2:$S$65,2,FALSE),"-") -> 10368 | K21: =IFERROR(VLOOKUP($B21,$V$2:$W$65,2,FALSE),"-") -> 5952 | L21: =IFERROR(VLOOKUP($B21,$Z$2:$AA$65,2,FALSE),"-") -> 4608 | M21: =IFERROR(VLOOKUP($B21,$AC$2:$AD$65,2,FALSE),"-") -> 7776 | O21: CDCLSA01 | P21: 120 | R21: CDCLSA03 | S21: 20 | V21: CDCLSA01 | W21: 190 | Z21: BSLASA10 | AA21: 288 | AC21: CDCLSA01 | AD21: 200
A22: The Select Aisle Baking Soda - 1kg | B22: BSLASA08 | C22: - | D22: - | E22: 121.82741 | F22: 83.682008 | G22: 160 | H22: 167.57493 | I22: =IFERROR(VLOOKUP($B22,$O$2:$P$55,2,FALSE),"-") -> - | J22: =IFERROR(VLOOKUP($B22,$R$2:$S$65,2,FALSE),"-") -> - | K22: =IFERROR(VLOOKUP($B22,$V$2:$W$65,2,FALSE),"-") -> - | L22: =IFERROR(VLOOKUP($B22,$Z$2:$AA$65,2,FALSE),"-") -> - | M22: =IFERROR(VLOOKUP($B22,$AC$2:$AD$65,2,FALSE),"-") -> - | O22: CDCLSA04 | P22: 160 | R22: CDCLSA04 | S22: 120 | V22: CDCLSA04 | W22: 120 | Z22: CDCLSA01 | AA22: 120 | AC22: CDCLSA04 | AD22: 160
A23: The Select Aisle Double Acting Baking Powder - 100g | B23: BSLASA05 | C23: 1783.9144 | D23: 1783.9144 | E23: 2844.856 | F23: 2128.5826 | G23: 4027.491 | H23: 3127.0974 | I23: =IFERROR(VLOOKUP($B23,$O$2:$P$55,2,FALSE),"-") -> 1344 | J23: =IFERROR(VLOOKUP($B23,$R$2:$S$65,2,FALSE),"-") -> 4512 | K23: =IFERROR(VLOOKUP($B23,$V$2:$W$65,2,FALSE),"-") -> 4704 | L23: =IFERROR(VLOOKUP($B23,$Z$2:$AA$65,2,FALSE),"-") -> 3840 | M23: =IFERROR(VLOOKUP($B23,$AC$2:$AD$65,2,FALSE),"-") -> 4896 | O23: CDCLSA05 | P23: 80 | R23: CDCLSA05 | S23: 180 | V23: CDCLSA05 | W23: 390 | Z23: CDCLSA04 | AA23: 160 | AC23: CDCLSA05 | AD23: 120
A24: The Select Aisle Dry Instant Yeast - 25g | B24: BIFISA07 | C24: 6696.1514 | D24: 6696.1514 | E24: 8807.2501 | F24: 8432.6158 | G24: 13209.215 | H24: 13200.026 | I24: =IFERROR(VLOOKUP($B24,$O$2:$P$55,2,FALSE),"-") -> 4032 | J24: =IFERROR(VLOOKUP($B24,$R$2:$S$65,2,FALSE),"-") -> 8496 | K24: =IFERROR(VLOOKUP($B24,$V$2:$W$65,2,FALSE),"-") -> 11088 | L24: =IFERROR(VLOOKUP($B24,$Z$2:$AA$65,2,FALSE),"-") -> 13968 | M24: =IFERROR(VLOOKUP($B24,$AC$2:$AD$65,2,FALSE),"-") -> 13536 | O24: CDCLSA06 | P24: 30 | R24: CDSPSA23 | S24: 576 | V24: CDCLSA06 | W24: 30 | Z24: CDCLSA05 | AA24: 120 | AC24: CDSPSA23 | AD24: 624
A25: The Select Aisle Dry Instant Yeast - 75g | B25: BIFISA03 | C25: 384.41841 | D25: 384.41841 | E25: 448.67968 | F25: 440.53764 | G25: 504.35118 | H25: 750.78864 | I25: =IFERROR(VLOOKUP($B25,$O$2:$P$55,2,FALSE),"-") -> 280 | J25: =IFERROR(VLOOKUP($B25,$R$2:$S$65,2,FALSE),"-") -> 392 | K25: =IFERROR(VLOOKUP($B25,$V$2:$W$65,2,FALSE),"-") -> 336 | L25: =IFERROR(VLOOKUP($B25,$Z$2:$AA$65,2,FALSE),"-") -> 504 | M25: =IFERROR(VLOOKUP($B25,$AC$2:$AD$65,2,FALSE),"-") -> 616 | O25: CDSPSA23 | P25: 336 | R25: CDSPSA24 | S25: 336 | V25: CDSPSA23 | W25: 576 | Z25: CDCLSA06 | AA25: 40 | AC25: CDSPSA24 | AD25: 240
A26: The Select Aisle Agar Agar - 20g | B26: BIFISA09 | C26: 2073.7746 | D26: 2073.7746 | E26: 1644.2924 | F26: 1511.2585 | G26: 939.81052 | H26: 786.44722 | I26: =IFERROR(VLOOKUP($B26,$O$2:$P$55,2,FALSE),"-") -> 1674 | J26: =IFERROR(VLOOKUP($B26,$R$2:$S$65,2,FALSE),"-") -> 3780 | K26: =IFERROR(VLOOKUP($B26,$V$2:$W$65,2,FALSE),"-") -> 2214 | L26: =IFERROR(VLOOKUP($B26,$Z$2:$AA$65,2,FALSE),"-") -> 540 | M26: =IFERROR(VLOOKUP($B26,$AC$2:$AD$65,2,FALSE),"-") -> 486 | O26: CDSPSA24 | P26: 384 | R26: CDSPSA40 | S26: 288 | V26: CDSPSA24 | W26: 192 | Z26: CDSPSA23 | AA26: 432 | AC26: CDSPSA40 | AD26: 672
A27: The Select Aisle Gelatin | B27: BIFISA11 | C27: 599.06764 | D27: 599.06764 | E27: 664.52457 | F27: 650.50231 | G27: 860.2276 | H27: 708.37067 | I27: =IFERROR(VLOOKUP($B27,$O$2:$P$55,2,FALSE),"-") -> 486 | J27: =IFERROR(VLOOKUP($B27,$R$2:$S$65,2,FALSE),"-") -> 702 | K27: =IFERROR(VLOOKUP($B27,$V$2:$W$65,2,FALSE),"-") -> 1026 | L27: =IFERROR(VLOOKUP($B27,$Z$2:$AA$65,2,FALSE),"-") -> 108 | M27: =IFERROR(VLOOKUP($B27,$AC$2:$AD$65,2,FALSE),"-") -> 324 | O27: CDSPSA40 | P27: 192 | R27: CDSPSA44 | S27: 192 | V27: CDSPSA40 | W27: 384 | Z27: CDSPSA24 | AA27: 144 | AC27: CDSPSA44 | AD27: 144
A28: The Select Aisle Citric Acid | B28: BSLASA10 | C28: 694.09098 | D28: 694.09098 | E28: 837.45899 | F28: 791.93213 | G28: 893.72337 | H28: 919.5525 | I28: =IFERROR(VLOOKUP($B28,$O$2:$P$55,2,FALSE),"-") -> 576 | J28: =IFERROR(VLOOKUP($B28,$R$2:$S$65,2,FALSE),"-") -> 792 | K28: =IFERROR(VLOOKUP($B28,$V$2:$W$65,2,FALSE),"-") -> 1008 | L28: =IFERROR(VLOOKUP($B28,$Z$2:$AA$65,2,FALSE),"-") -> 288 | M28: =IFERROR(VLOOKUP($B28,$AC$2:$AD$65,2,FALSE),"-") -> 816 | O28: CDSPSA44 | P28: 48 | R28: CDSPSA54 | S28: 240 | V28: CDSPSA44 | W28: 336 | Z28: CDSPSA40 | AA28: 336 | AC28: CDSPSA54 | AD28: 240
A29: The Select Aisle Corn Flour | B29: BIFISA10 | C29: 1649.5318 | D29: 1649.5318 | E29: 1645.0427 | F29: 2271.2267 | G29: 2799.6242 | H29: 4125.3887 | I29: =IFERROR(VLOOKUP($B29,$O$2:$P$55,2,FALSE),"-") -> 1080 | J29: =IFERROR(VLOOKUP($B29,$R$2:$S$65,2,FALSE),"-") -> 2160 | K29: =IFERROR(VLOOKUP($B29,$V$2:$W$65,2,FALSE),"-") -> 1872 | L29: =IFERROR(VLOOKUP($B29,$Z$2:$AA$65,2,FALSE),"-") -> 1980 | M29: =IFERROR(VLOOKUP($B29,$AC$2:$AD$65,2,FALSE),"-") -> 2484 | O29: CDSPSA54 | P29: 240 | R29: CDTFSA01 | S29: 1008 | V29: CDSPSA54 | W29: 288 | Z29: CDSPSA44 | AA29: 240 | AC29: CDTFSA01 | AD29: 792
A30: The Select Aisle Icing Sugar 300g | B30: BISWSA05 | C30: 331.32295 | D30: 331.32295 | E30: 431.68207 | F30: 344.83402 | G30: 428.41705 | H30: 346.37993 | I30: =IFERROR(VLOOKUP($B30,$O$2:$P$55,2,FALSE),"-") -> 336 | J30: =IFERROR(VLOOKUP($B30,$R$2:$S$65,2,FALSE),"-") -> 336 | K30: =IFERROR(VLOOKUP($B30,$V$2:$W$65,2,FALSE),"-") -> 336 | L30: =IFERROR(VLOOKUP($B30,$Z$2:$AA$65,2,FALSE),"-") -> 168 | M30: =IFERROR(VLOOKUP($B30,$AC$2:$AD$65,2,FALSE),"-") -> 504 | O30: CDTFSA01 | P30: 1212 | R30: CHCCSA33 | S30: 3384 | V30: CDTFSA01 | W30: 1368 | Z30: CDSPSA54 | AA30: 96 | AC30: CHCCSA33 | AD30: 2592
A31: The Select Aisle T55 Baking Flour - 453g | B31: BSFLSA03 | C31: 0 | D31: 0 | E31: 0 | F31: 0 | G31: 0 | H31: 0 | I31: =IFERROR(VLOOKUP($B31,$O$2:$P$55,2,FALSE),"-") -> 96 | J31: =IFERROR(VLOOKUP($B31,$R$2:$S$65,2,FALSE),"-") -> - | K31: =IFERROR(VLOOKUP($B31,$V$2:$W$65,2,FALSE),"-") -> 24 | L31: =IFERROR(VLOOKUP($B31,$Z$2:$AA$65,2,FALSE),"-") -> 120 | M31: =IFERROR(VLOOKUP($B31,$AC$2:$AD$65,2,FALSE),"-") -> - | O31: CHCCSA33 | P31: 2712 | R31: CHCCSA34 | S31: 480 | V31: CHCCSA33 | W31: 2736 | Z31: CDTFSA01 | AA31: 648 | AC31: CHCCSA34 | AD31: 432
A32: Colours & Flavours | O32: CHCCSA34 | P32: 384 | R32: CHCCSA35 | S32: 4536 | V32: CHCCSA34 | W32: 480 | Z32: CHCCSA33 | AA32: 2952 | AC32: CHCCSA35 | AD32: 3300
A33: The Select Aisle Vanilla Essence 30 ml | B33: BIEFSA15 | C33: 5529.2667 | D33: 5529.2667 | E33: 5138.2702 | F33: 8306.8827 | G33: 9299.8431 | H33: 10144.435 | I33: =IFERROR(VLOOKUP($B33,$O$2:$P$55,2,FALSE),"-") -> 6240 | J33: =IFERROR(VLOOKUP($B33,$R$2:$S$65,2,FALSE),"-") -> 10368 | K33: =IFERROR(VLOOKUP($B33,$V$2:$W$65,2,FALSE),"-") -> 13440 | L33: =IFERROR(VLOOKUP($B33,$Z$2:$AA$65,2,FALSE),"-") -> 10656 | M33: =IFERROR(VLOOKUP($B33,$AC$2:$AD$65,2,FALSE),"-") -> 6144 | O33: CHCCSA35 | P33: 3096 | R33: CHCCSA48 | S33: 5220 | V33: CHCCSA35 | W33: 4536 | Z33: CHCCSA34 | AA33: 336 | AC33: CHCCSA36 | AD33: 96
A34: The Select Aisle Vanilla Flavour - 100ml | B34: BIEFSA01 | C34: 1296.0849 | D34: 1296.0849 | E34: 2177.2658 | F34: 1670.1675 | G34: 2290.3179 | H34: 2146.3812 | I34: =IFERROR(VLOOKUP($B34,$O$2:$P$55,2,FALSE),"-") -> 336 | J34: =IFERROR(VLOOKUP($B34,$R$2:$S$65,2,FALSE),"-") -> 2112 | K34: =IFERROR(VLOOKUP($B34,$V$2:$W$65,2,FALSE),"-") -> 4560 | L34: =IFERROR(VLOOKUP($B34,$Z$2:$AA$65,2,FALSE),"-") -> 2352 | M34: =IFERROR(VLOOKUP($B34,$AC$2:$AD$65,2,FALSE),"-") -> 1536 | O34: CHCCSA48 | P34: 5280 | R34: CHCCSA49 | S34: 3600 | V34: CHCCSA48 | W34: 4320 | Z34: CHCCSA35 | AA34: 5256 | AC34: CHCCSA48 | AD34: 3780
A35: The Select Aisle Vanilla Extract - 30ml | B35: BIEFSA16 | C35: 679.0162 | D35: 679.0162 | E35: 827.91415 | F35: 691.01109 | G35: 1275.441 | H35: 1142.4285 | I35: =IFERROR(VLOOKUP($B35,$O$2:$P$55,2,FALSE),"-") -> 448 | J35: =IFERROR(VLOOKUP($B35,$R$2:$S$65,2,FALSE),"-") -> 1124 | K35: =IFERROR(VLOOKUP($B35,$V$2:$W$65,2,FALSE),"-") -> 1248 | L35: =IFERROR(VLOOKUP($B35,$Z$2:$AA$65,2,FALSE),"-") -> 1040 | M35: =IFERROR(VLOOKUP($B35,$AC$2:$AD$65,2,FALSE),"-") -> 960 | O35: CHCCSA49 | P35: 2700 | R35: CHCCSA50 | S35: 990 | V35: CHCCSA49 | W35: 2160 | Z35: CHCCSA36 | AC35: CHCCSA49 | AD35: 1260
A36: The Select Aisle Yellow Gel Food Colour 30ml | B36: CDCLSA05 | C36: 146.58353 | D36: 146.58353 | E36: 139.64746 | F36: 130.23789 | G36: 156.79973 | H36: 128 | I36: =IFERROR(VLOOKUP($B36,$O$2:$P$55,2,FALSE),"-") -> 80 | J36: =IFERROR(VLOOKUP($B36,$R$2:$S$65,2,FALSE),"-") -> 180 | K36: =IFERROR(VLOOKUP($B36,$V$2:$W$65,2,FALSE),"-") -> 390 | L36: =IFERROR(VLOOKUP($B36,$Z$2:$AA$65,2,FALSE),"-") -> 120 | M36: =IFERROR(VLOOKUP($B36,$AC$2:$AD$65,2,FALSE),"-") -> 120 | O36: CHCCSA50 | P36: 270 | R36: CHCCSSA01 | S36: 2000 | V36: CHCCSA50 | W36: 1260 | Z36: CHCCSA48 | AA36: 4320 | AC36: CHCCSA50 | AD36: 540
A37: The Select Aisle Red Gel Food Colour 30ml | B37: CDCLSA01 | C37: 261.14286 | D37: 261.14286 | E37: 214.28464 | F37: 170.61287 | G37: 240.87538 | H37: 211.17143 | I37: =IFERROR(VLOOKUP($B37,$O$2:$P$55,2,FALSE),"-") -> 120 | J37: =IFERROR(VLOOKUP($B37,$R$2:$S$65,2,FALSE),"-") -> 200 | K37: =IFERROR(VLOOKUP($B37,$V$2:$W$65,2,FALSE),"-") -> 190 | L37: =IFERROR(VLOOKUP($B37,$Z$2:$AA$65,2,FALSE),"-") -> 120 | M37: =IFERROR(VLOOKUP($B37,$AC$2:$AD$65,2,FALSE),"-") -> 200 | O37: CHCCSSA01 | P37: 1780 | R37: CHCOSA01 | S37: 200 | V37: CHCCSSA01 | W37: 3520 | Z37: CHCCSA49 | AA37: 1800 | AC37: CHCCSA52 | AD37: 24
A38: The Select Aisle Dark Green Gel Food Colour 30ml | B38: CDCLSA02 | C38: 0 | D38: 0 | E38: - | F38: - | G38: - | H38: 0 | I38: =IFERROR(VLOOKUP($B38,$O$2:$P$55,2,FALSE),"-") -> - | J38: =IFERROR(VLOOKUP($B38,$R$2:$S$65,2,FALSE),"-") -> - | K38: =IFERROR(VLOOKUP($B38,$V$2:$W$65,2,FALSE),"-") -> - | L38: =IFERROR(VLOOKUP($B38,$Z$2:$AA$65,2,FALSE),"-") -> - | M38: =IFERROR(VLOOKUP($B38,$AC$2:$AD$65,2,FALSE),"-") -> - | O38: CHCOSA01 | P38: 80 | R38: CHCOSA06 | S38: 3136 | V38: CHCOSA01 | W38: 280 | Z38: CHCCSA50 | AA38: 270 | AC38: CHCCSA53 | AD38: 24
A39: The Select Aisle Dark Blue Gel Food Colour 30ml | B39: CDCLSA03 | C39: 0 | D39: 0 | E39: 0 | F39: 0 | G39: 0 | H39: 0 | I39: =IFERROR(VLOOKUP($B39,$O$2:$P$55,2,FALSE),"-") -> - | J39: =IFERROR(VLOOKUP($B39,$R$2:$S$65,2,FALSE),"-") -> 20 | K39: =IFERROR(VLOOKUP($B39,$V$2:$W$65,2,FALSE),"-") -> - | L39: =IFERROR(VLOOKUP($B39,$Z$2:$AA$65,2,FALSE),"-") -> - | M39: =IFERROR(VLOOKUP($B39,$AC$2:$AD$65,2,FALSE),"-") -> - | O39: CHCOSA06 | P39: 1536 | R39: CHCSSA02 | S39: 420 | V39: CHCOSA06 | W39: 3200 | Z39: CHCCSA52 | AA39: 88 | AC39: CHCCSSA01 | AD39: 3820
A40: The Select Aisle Sky Blue Gel Food Colour 30ml | B40: CDCLSA04 | C40: 168.14738 | D40: 168.14738 | E40: 192.54914 | F40: 135.23161 | G40: 301.72823 | H40: 219.96818 | I40: =IFERROR(VLOOKUP($B40,$O$2:$P$55,2,FALSE),"-") -> 160 | J40: =IFERROR(VLOOKUP($B40,$R$2:$S$65,2,FALSE),"-") -> 120 | K40: =IFERROR(VLOOKUP($B40,$V$2:$W$65,2,FALSE),"-") -> 120 | L40: =IFERROR(VLOOKUP($B40,$Z$2:$AA$65,2,FALSE),"-") -> 160 | M40: =IFERROR(VLOOKUP($B40,$AC$2:$AD$65,2,FALSE),"-") -> 160 | O40: CHCSSA02 | P40: 180 | R40: CHCSSA03 | S40: 480 | V40: CHCSSA02 | W40: 960 | Z40: CHCCSA53 | AA40: 88 | AC40: CHCOSA01 | AD40: 300
...

Sheet Chennai DP
C1: Demand Plan | I1: Primary Sales
B2: SKU Code | C2: 46113 | D2: 46143 | E2: 46174 | F2: 46204 | G2: 46235 | H2: 46266 | I2: 46113 | J2: 46143 | K2: 46174 | L2: 46204 | M2: 46235
A3: Product | C3: TOTAL (in pcs) | D3: TOTAL (in pcs) | E3: TOTAL (in pcs) | F3: TOTAL (in pcs) | G3: TOTAL (in pcs) | H3: TOTAL (in pcs) | I3: TOTAL (in pcs) | J3: TOTAL (in pcs) | K3: TOTAL (in pcs) | L3: TOTAL (in pcs) | M3: TOTAL (in pcs) | Q3: Row Labels | R3: 46113 | T3: Row Labels | U3: 46143 | W3: Row Labels | X3: 46174 | Z3: Row Labels | AA3: 46204 | AC3: Row Labels | AD3: 46235
A4: Compound Chocolate & Cocoa | Q4: 30SAMC47 | R4: 50 | T4: ACSAPM01 | U4: 20 | W4: ACSAPM01 | X4: 40 | Z4: BIBMSA01 | AA4: 1560 | AC4: BIBMSA01 | AD4: 650
A5: The Select Aisle Dark Compound Chocolate Chips - 150g | B5: CHCCSA35 | C5: 9616.9545 | D5: 9616.9545 | E5: 1835.6735 | F5: 2478.431 | G5: 3777.6242 | H5: 3176.9858 | I5: =IFERROR(VLOOKUP($B5,$Q$2:$R$81,2,FALSE),"-") -> 22509 | J5: =IFERROR(VLOOKUP($B5,$T$2:$U$81,2,FALSE),"-") -> 18720 | K5: =IFERROR(VLOOKUP($B5,$W$2:$X$81,2,FALSE),"-") -> 7503 | L5: =IFERROR(VLOOKUP($B5,$Z$2:$AA$81,2,FALSE),"-") -> 7248 | M5: =IFERROR(VLOOKUP($B5,$AC$2:$AD$81,2,FALSE),"-") -> 4392 | Q5: BIBMSA01 | R5: 804 | T5: BIBMSA01 | U5: 1612 | W5: BIBMSA01 | X5: 1120 | Z5: BICCPSA01 | AA5: 1849 | AC5: BICCPSA01 | AD5: 42
A6: TSA Dark Compound Chocolate Chips 50g | B6: CHCCSA48 | C6: 11794.736 | D6: 11794.736 | E6: 1611.481 | F6: 2931.1671 | G6: 3357.6629 | H6: 3285.6037 | I6: =IFERROR(VLOOKUP($B6,$Q$2:$R$81,2,FALSE),"-") -> 38070 | J6: =IFERROR(VLOOKUP($B6,$T$2:$U$81,2,FALSE),"-") -> 27900 | K6: =IFERROR(VLOOKUP($B6,$W$2:$X$81,2,FALSE),"-") -> 8460 | L6: =IFERROR(VLOOKUP($B6,$Z$2:$AA$81,2,FALSE),"-") -> 5376 | M6: =IFERROR(VLOOKUP($B6,$AC$2:$AD$81,2,FALSE),"-") -> 10500 | Q6: BICCPSA01 | R6: 516 | T6: BICCPSA01 | U6: 1589 | W6: BICCPSA01 | X6: 1854 | Z6: BICPSA01 | AA6: 5999 | AC6: BICPSA01 | AD6: 3728
A7: The Select Aisle's Dark Chocolate Chips - 250g | B7: CHCCSA47 | C7: - | D7: - | E7: - | F7: - | G7: - | H7: - | I7: =IFERROR(VLOOKUP($B7,$Q$2:$R$81,2,FALSE),"-") -> - | J7: =IFERROR(VLOOKUP($B7,$T$2:$U$81,2,FALSE),"-") -> - | K7: =IFERROR(VLOOKUP($B7,$W$2:$X$81,2,FALSE),"-") -> - | L7: =IFERROR(VLOOKUP($B7,$Z$2:$AA$81,2,FALSE),"-") -> - | M7: =IFERROR(VLOOKUP($B7,$AC$2:$AD$81,2,FALSE),"-") -> - | Q7: BICPSA01 | R7: 1937 | T7: BICPSA01 | U7: 5386 | W7: BICPSA01 | X7: 9207 | Z7: BICPSA02 | AA7: 8737 | AC7: BICPSA02 | AD7: 5884
A8: The Select Aisle Milk Compound Chocolate Chips - 150g | B8: CHCCSA33 | C8: 8249.0372 | D8: 8249.0372 | E8: 1958.9953 | F8: 2279.3324 | G8: 3134.1589 | H8: 2624.2969 | I8: =IFERROR(VLOOKUP($B8,$Q$2:$R$81,2,FALSE),"-") -> 12936 | J8: =IFERROR(VLOOKUP($B8,$T$2:$U$81,2,FALSE),"-") -> 14472 | K8: =IFERROR(VLOOKUP($B8,$W$2:$X$81,2,FALSE),"-") -> 6434 | L8: =IFERROR(VLOOKUP($B8,$Z$2:$AA$81,2,FALSE),"-") -> 5304 | M8: =IFERROR(VLOOKUP($B8,$AC$2:$AD$81,2,FALSE),"-") -> 4032 | Q8: BICPSA02 | R8: 2554 | T8: BICPSA02 | U8: 8294 | W8: BICPSA02 | X8: 11966 | Z8: BIEFSA01 | AA8: 3409 | AC8: BIEFSA01 | AD8: 1738
A9: TSA Milk Compound Chocolate Chips 50g | B9: CHCCSA49 | C9: 17103.009 | D9: 17103.009 | E9: 399.59549 | F9: 1559.7768 | G9: 1492.751 | H9: 1696.9434 | I9: =IFERROR(VLOOKUP($B9,$Q$2:$R$81,2,FALSE),"-") -> 27990 | J9: =IFERROR(VLOOKUP($B9,$T$2:$U$81,2,FALSE),"-") -> 21780 | K9: =IFERROR(VLOOKUP($B9,$W$2:$X$81,2,FALSE),"-") -> 5760 | L9: =IFERROR(VLOOKUP($B9,$Z$2:$AA$81,2,FALSE),"-") -> 3193 | M9: =IFERROR(VLOOKUP($B9,$AC$2:$AD$81,2,FALSE),"-") -> 2256 | Q9: BIEFSA01 | R9: 3315 | T9: BIEFSA01 | U9: 14112 | W9: BIEFSA01 | X9: 5091 | Z9: BIEFSA15 | AA9: 118752 | AC9: BIEFSA15 | AD9: 22464
A10: The Select Aisle White Compound Chocolate Chips | B10: CHCCSA34 | C10: 2049.6049 | D10: 2049.6049 | E10: 572.3243 | F10: 458.61943 | G10: 769.33672 | H10: 924.83405 | I10: =IFERROR(VLOOKUP($B10,$Q$2:$R$81,2,FALSE),"-") -> 3408 | J10: =IFERROR(VLOOKUP($B10,$T$2:$U$81,2,FALSE),"-") -> 3360 | K10: =IFERROR(VLOOKUP($B10,$W$2:$X$81,2,FALSE),"-") -> 2482 | L10: =IFERROR(VLOOKUP($B10,$Z$2:$AA$81,2,FALSE),"-") -> 2016 | M10: =IFERROR(VLOOKUP($B10,$AC$2:$AD$81,2,FALSE),"-") -> 1632 | Q10: BIEFSA15 | R10: 54624 | T10: BIEFSA15 | U10: 92874 | W10: BIEFSA15 | X10: 129640 | Z10: BIEFSA16 | AA10: 21094 | AC10: BIEFSA16 | AD10: 19808
A11: The Select Aisle Twin Chocolate Chips 50g | B11: CHCCSA50 | C11: 414.15458 | D11: 414.15458 | E11: 238.53628 | F11: 317.63563 | G11: 200.41365 | H11: 297.38692 | I11: =IFERROR(VLOOKUP($B11,$Q$2:$R$81,2,FALSE),"-") -> 6597 | J11: =IFERROR(VLOOKUP($B11,$T$2:$U$81,2,FALSE),"-") -> 11790 | K11: =IFERROR(VLOOKUP($B11,$W$2:$X$81,2,FALSE),"-") -> 11052 | L11: =IFERROR(VLOOKUP($B11,$Z$2:$AA$81,2,FALSE),"-") -> 12600 | M11: =IFERROR(VLOOKUP($B11,$AC$2:$AD$81,2,FALSE),"-") -> 5940 | Q11: BIEFSA16 | R11: 6531 | T11: BIEFSA16 | U11: 9462 | W11: BIEFSA16 | X11: 14944 | Z11: BIFISA03 | AA11: 16472 | AC11: BIFISA03 | AD11: 17332
A12: The Select Aisle Dark Compound Chocolate Slab 500g | B12: CHCCSSA01 | C12: 15179.702 | D12: 15179.702 | E12: 2998.9972 | F12: 3425.2604 | G12: 4001.484 | H12: 3069.1697 | I12: =IFERROR(VLOOKUP($B12,$Q$2:$R$81,2,FALSE),"-") -> 9936 | J12: =IFERROR(VLOOKUP($B12,$T$2:$U$81,2,FALSE),"-") -> 13820 | K12: =IFERROR(VLOOKUP($B12,$W$2:$X$81,2,FALSE),"-") -> 5366 | L12: =IFERROR(VLOOKUP($B12,$Z$2:$AA$81,2,FALSE),"-") -> 6960 | M12: =IFERROR(VLOOKUP($B12,$AC$2:$AD$81,2,FALSE),"-") -> 5620 | Q12: BIFISA03 | R12: 5824 | T12: BIFISA03 | U12: 9376 | W12: BIFISA03 | X12: 5330 | Z12: BIFISA07 | AA12: 186262 | AC12: BIFISA07 | AD12: 236618
A13: The Select Aisle Milk Compound Chocolate Bar 500 g | B13: CHCSSA04 | C13: - | D13: - | E13: 162.5 | F13: 85.903084 | G13: 174.96528 | H13: 214.35067 | I13: =IFERROR(VLOOKUP($B13,$Q$2:$R$81,2,FALSE),"-") -> 1116 | J13: =IFERROR(VLOOKUP($B13,$T$2:$U$81,2,FALSE),"-") -> 3220 | K13: =IFERROR(VLOOKUP($B13,$W$2:$X$81,2,FALSE),"-") -> 1144 | L13: =IFERROR(VLOOKUP($B13,$Z$2:$AA$81,2,FALSE),"-") -> 240 | M13: =IFERROR(VLOOKUP($B13,$AC$2:$AD$81,2,FALSE),"-") -> 320 | Q13: BIFISA07 | R13: 55959 | T13: BIFISA07 | U13: 123696 | W13: BIFISA07 | X13: 190300 | Z13: BIFISA09 | AA13: 5400 | AC13: BIFISA09 | AD13: 6164
A14: The Select Aisle White Compound Chocolate Bar 500 g | B14: CHCSSA05 | C14: - | D14: - | E14: 140 | F14: 97.172237 | G14: 140.80497 | H14: 194.94331 | I14: =IFERROR(VLOOKUP($B14,$Q$2:$R$81,2,FALSE),"-") -> 916 | J14: =IFERROR(VLOOKUP($B14,$T$2:$U$81,2,FALSE),"-") -> 2371 | K14: =IFERROR(VLOOKUP($B14,$W$2:$X$81,2,FALSE),"-") -> 977 | L14: =IFERROR(VLOOKUP($B14,$Z$2:$AA$81,2,FALSE),"-") -> 300 | M14: =IFERROR(VLOOKUP($B14,$AC$2:$AD$81,2,FALSE),"-") -> 60 | Q14: BIFISA09 | R14: 14283 | T14: BIFISA09 | U14: 22597 | W14: BIFISA09 | X14: 20808 | Z14: BIFISA10 | AA14: 103693 | AC14: BIFISA10 | AD14: 104634
A15: The Select Aisle Dark Compound Chocolate Slab 150g | B15: CHCSSA02 | C15: 2923.3526 | D15: 2923.3526 | E15: 663.34765 | F15: 616.04292 | G15: 555.29969 | H15: 422.44313 | I15: =IFERROR(VLOOKUP($B15,$Q$2:$R$81,2,FALSE),"-") -> 750 | J15: =IFERROR(VLOOKUP($B15,$T$2:$U$81,2,FALSE),"-") -> 2880 | K15: =IFERROR(VLOOKUP($B15,$W$2:$X$81,2,FALSE),"-") -> 3660 | L15: =IFERROR(VLOOKUP($B15,$Z$2:$AA$81,2,FALSE),"-") -> 1920 | M15: =IFERROR(VLOOKUP($B15,$AC$2:$AD$81,2,FALSE),"-") -> 420 | Q15: BIFISA10 | R15: 23189 | T15: BIFISA10 | U15: 51176 | W15: BIFISA10 | X15: 85650 | Z15: BIFISA11 | AA15: 8005 | AC15: BIFISA11 | AD15: 2508
A16: The Select Aisle Milk Compound Chocolate Slab 150g | B16: CHCSSA03 | C16: 2136.8518 | D16: 2136.8518 | E16: 563.57861 | F16: 422.31179 | G16: 368.4304 | H16: 306.62703 | I16: =IFERROR(VLOOKUP($B16,$Q$2:$R$81,2,FALSE),"-") -> 1170 | J16: =IFERROR(VLOOKUP($B16,$T$2:$U$81,2,FALSE),"-") -> 2580 | K16: =IFERROR(VLOOKUP($B16,$W$2:$X$81,2,FALSE),"-") -> 2400 | L16: =IFERROR(VLOOKUP($B16,$Z$2:$AA$81,2,FALSE),"-") -> 960 | M16: =IFERROR(VLOOKUP($B16,$AC$2:$AD$81,2,FALSE),"-") -> 480 | Q16: BIFISA11 | R16: 5688 | T16: BIFISA11 | U16: 8695 | W16: BIFISA11 | X16: 17226 | Z16: BIFISA12 | AC16: BIFISA12 | AD16: 1280
A17: The Select Aisle Cocoa Powder 70g | B17: CHCOSA06 | C17: 6682.0499 | D17: 6682.0499 | E17: 1602.078 | F17: 1951.8906 | G17: 3141.9704 | H17: 1998.1354 | I17: =IFERROR(VLOOKUP($B17,$Q$2:$R$81,2,FALSE),"-") -> 9028 | J17: =IFERROR(VLOOKUP($B17,$T$2:$U$81,2,FALSE),"-") -> 20864 | K17: =IFERROR(VLOOKUP($B17,$W$2:$X$81,2,FALSE),"-") -> 34184 | L17: =IFERROR(VLOOKUP($B17,$Z$2:$AA$81,2,FALSE),"-") -> 32640 | M17: =IFERROR(VLOOKUP($B17,$AC$2:$AD$81,2,FALSE),"-") -> 15782 | Q17: BIMCSA01 | R17: 1713 | T17: BIMCSA01 | U17: 3352 | W17: BIMCSA01 | X17: 4004 | Z17: BIMCSA01 | AA17: 3304 | AC17: BIMCSA01 | AD17: 2956
A18: The Select Aisle Dutch Processed Cocoa Powder 250g | B18: CHCOSA01 | C18: 227.76096 | D18: 227.76096 | E18: 82.123098 | F18: 110.95306 | G18: 142.99515 | H18: 107.19066 | I18: =IFERROR(VLOOKUP($B18,$Q$2:$R$81,2,FALSE),"-") -> 640 | J18: =IFERROR(VLOOKUP($B18,$T$2:$U$81,2,FALSE),"-") -> 960 | K18: =IFERROR(VLOOKUP($B18,$W$2:$X$81,2,FALSE),"-") -> 1440 | L18: =IFERROR(VLOOKUP($B18,$Z$2:$AA$81,2,FALSE),"-") -> 1700 | M18: =IFERROR(VLOOKUP($B18,$AC$2:$AD$81,2,FALSE),"-") -> 900 | Q18: BISWSA05 | R18: 3758 | T18: BISWSA05 | U18: 4142 | W18: BISWSA05 | X18: 5144 | Z18: BISWSA05 | AA18: 4620 | AC18: BISWSA05 | AD18: 7722
A19: The Select Aisle Drinking Chocolate 200g | B19: SAHC02 | C19: 1942.5508 | D19: 1942.5508 | E19: 355.05574 | F19: 368.325 | G19: 420.93558 | H19: 495.60306 | I19: =IFERROR(VLOOKUP($B19,$Q$2:$R$81,2,FALSE),"-") -> 4277 | J19: =IFERROR(VLOOKUP($B19,$T$2:$U$81,2,FALSE),"-") -> 2208 | K19: =IFERROR(VLOOKUP($B19,$W$2:$X$81,2,FALSE),"-") -> 3434 | L19: =IFERROR(VLOOKUP($B19,$Z$2:$AA$81,2,FALSE),"-") -> 10400 | M19: =IFERROR(VLOOKUP($B19,$AC$2:$AD$81,2,FALSE),"-") -> 8128 | Q19: BSFLSA03 | R19: 230 | T19: BSFLSA03 | U19: 360 | W19: BISWSA06 | X19: 384 | Z19: BISWSA06 | AA19: 744 | AC19: BSFLSA03 | AD19: 336
A20: Functional Ingredients | Q20: BSLASA04 | R20: 19079 | T20: BSLASA04 | U20: 40608 | W20: BSFLSA03 | X20: 480 | Z20: BSFLSA03 | AA20: 312 | AC20: BSLASA04 | AD20: 7872
A21: The Select Aisle Baking Soda - 100g | B21: BSLASA04 | C21: 14983.44 | D21: 14983.44 | E21: 5038.3311 | F21: 4741.6135 | G21: 3224.4523 | H21: 2995.7338 | I21: =IFERROR(VLOOKUP($B21,$Q$2:$R$81,2,FALSE),"-") -> 19079 | J21: =IFERROR(VLOOKUP($B21,$T$2:$U$81,2,FALSE),"-") -> 40608 | K21: =IFERROR(VLOOKUP($B21,$W$2:$X$81,2,FALSE),"-") -> 16738 | L21: =IFERROR(VLOOKUP($B21,$Z$2:$AA$81,2,FALSE),"-") -> 11520 | M21: =IFERROR(VLOOKUP($B21,$AC$2:$AD$81,2,FALSE),"-") -> 7872 | Q21: BSLASA05 | R21: 14271 | T21: BSLASA05 | U21: 12552 | W21: BSLASA01 | X21: 16 | Z21: BSLASA04 | AA21: 11520 | AC21: BSLASA05 | AD21: 5088
A22: The Select Aisle Baking Soda - 1kg | B22: BSLASA08 | C22: 650 | D22: 650 | E22: 150 | F22: 33.472803 | G22: 0 | H22: 61.307902 | I22: =IFERROR(VLOOKUP($B22,$Q$2:$R$81,2,FALSE),"-") -> 228 | J22: =IFERROR(VLOOKUP($B22,$T$2:$U$81,2,FALSE),"-") -> 336 | K22: =IFERROR(VLOOKUP($B22,$W$2:$X$81,2,FALSE),"-") -> 324 | L22: =IFERROR(VLOOKUP($B22,$Z$2:$AA$81,2,FALSE),"-") -> 420 | M22: =IFERROR(VLOOKUP($B22,$AC$2:$AD$81,2,FALSE),"-") -> 102 | Q22: BSLASA08 | R22: 228 | T22: BSLASA08 | U22: 336 | W22: BSLASA04 | X22: 16738 | Z22: BSLASA05 | AA22: 8736 | AC22: BSLASA08 | AD22: 102
A23: The Select Aisle Double Acting Baking Powder - 100g | B23: BSLASA05 | C23: 10767.992 | D23: 10767.992 | E23: 2790.555 | F23: 1955.3552 | G23: 3070.7854 | H23: 1463.4293 | I23: =IFERROR(VLOOKUP($B23,$Q$2:$R$81,2,FALSE),"-") -> 14271 | J23: =IFERROR(VLOOKUP($B23,$T$2:$U$81,2,FALSE),"-") -> 12552 | K23: =IFERROR(VLOOKUP($B23,$W$2:$X$81,2,FALSE),"-") -> 11049 | L23: =IFERROR(VLOOKUP($B23,$Z$2:$AA$81,2,FALSE),"-") -> 8736 | M23: =IFERROR(VLOOKUP($B23,$AC$2:$AD$81,2,FALSE),"-") -> 5088 | Q23: BSLASA10 | R23: 7403 | T23: BSLASA10 | U23: 8928 | W23: BSLASA05 | X23: 11049 | Z23: BSLASA08 | AA23: 420 | AC23: BSLASA10 | AD23: 21410
A24: The Select Aisle Dry Instant Yeast - 25g | B24: BIFISA07 | C24: 47442.911 | D24: 47442.911 | E24: 5849.2702 | F24: 5168.3824 | G24: 7917.9273 | H24: 7339.5976 | I24: =IFERROR(VLOOKUP($B24,$Q$2:$R$81,2,FALSE),"-") -> 55959 | J24: =IFERROR(VLOOKUP($B24,$T$2:$U$81,2,FALSE),"-") -> 123696 | K24: =IFERROR(VLOOKUP($B24,$W$2:$X$81,2,FALSE),"-") -> 190300 | L24: =IFERROR(VLOOKUP($B24,$Z$2:$AA$81,2,FALSE),"-") -> 186262 | M24: =IFERROR(VLOOKUP($B24,$AC$2:$AD$81,2,FALSE),"-") -> 236618 | Q24: BSLASA25 | R24: 1 | T24: CDCLSA01 | U24: 2430 | W24: BSLASA08 | X24: 324 | Z24: BSLASA10 | AA24: 17064 | AC24: BSLASA25 | AD24: 1
A25: The Select Aisle Dry Instant Yeast - 75g | B25: BIFISA03 | C25: 3005.6884 | D25: 3005.6884 | E25: 264.28346 | F25: 258.16111 | G25: 352.39666 | H25: 306.36155 | I25: =IFERROR(VLOOKUP($B25,$Q$2:$R$81,2,FALSE),"-") -> 5824 | J25: =IFERROR(VLOOKUP($B25,$T$2:$U$81,2,FALSE),"-") -> 9376 | K25: =IFERROR(VLOOKUP($B25,$W$2:$X$81,2,FALSE),"-") -> 5330 | L25: =IFERROR(VLOOKUP($B25,$Z$2:$AA$81,2,FALSE),"-") -> 16472 | M25: =IFERROR(VLOOKUP($B25,$AC$2:$AD$81,2,FALSE),"-") -> 17332 | Q25: CDCLSA01 | R25: 1468 | T25: CDCLSA02 | U25: 90 | W25: BSLASA10 | X25: 11520 | Z25: BSLASA25 | AC25: CDCLSA01 | AD25: 1040
A26: The Select Aisle Agar Agar - 20g | B26: BIFISA09 | C26: 8615.7562 | D26: 8615.7562 | E26: 1362.371 | F26: 1281.3669 | G26: 1115.8079 | H26: 829.91842 | I26: =IFERROR(VLOOKUP($B26,$Q$2:$R$81,2,FALSE),"-") -> 14283 | J26: =IFERROR(VLOOKUP($B26,$T$2:$U$81,2,FALSE),"-") -> 22597 | K26: =IFERROR(VLOOKUP($B26,$W$2:$X$81,2,FALSE),"-") -> 20808 | L26: =IFERROR(VLOOKUP($B26,$Z$2:$AA$81,2,FALSE),"-") -> 5400 | M26: =IFERROR(VLOOKUP($B26,$AC$2:$AD$81,2,FALSE),"-") -> 6164 | Q26: CDCLSA02 | R26: 110 | T26: CDCLSA03 | U26: 120 | W26: CDCLSA01 | X26: 1319 | Z26: CDCLSA01 | AA26: 1120 | AC26: CDCLSA04 | AD26: 860
A27: The Select Aisle Gelatin | B27: BIFISA11 | C27: 3080.6595 | D27: 3080.6595 | E27: 491.57775 | F27: 504.75297 | G27: 552.97134 | H27: 565.51658 | I27: =IFERROR(VLOOKUP($B27,$Q$2:$R$81,2,FALSE),"-") -> 5688 | J27: =IFERROR(VLOOKUP($B27,$T$2:$U$81,2,FALSE),"-") -> 8695 | K27: =IFERROR(VLOOKUP($B27,$W$2:$X$81,2,FALSE),"-") -> 17226 | L27: =IFERROR(VLOOKUP($B27,$Z$2:$AA$81,2,FALSE),"-") -> 8005 | M27: =IFERROR(VLOOKUP($B27,$AC$2:$AD$81,2,FALSE),"-") -> 2508 | Q27: CDCLSA03 | R27: 100 | T27: CDCLSA04 | U27: 1730 | W27: CDCLSA02 | X27: 30 | Z27: CDCLSA04 | AA27: 971 | AC27: CDCLSA05 | AD27: 200
A28: The Select Aisle Citric Acid | B28: BSLASA10 | C28: 864.56946 | D28: 864.56946 | E28: 123.15573 | F28: 265.47725 | G28: 361.18024 | H28: 488.92362 | I28: =IFERROR(VLOOKUP($B28,$Q$2:$R$81,2,FALSE),"-") -> 7403 | J28: =IFERROR(VLOOKUP($B28,$T$2:$U$81,2,FALSE),"-") -> 8928 | K28: =IFERROR(VLOOKUP($B28,$W$2:$X$81,2,FALSE),"-") -> 11520 | L28: =IFERROR(VLOOKUP($B28,$Z$2:$AA$81,2,FALSE),"-") -> 17064 | M28: =IFERROR(VLOOKUP($B28,$AC$2:$AD$81,2,FALSE),"-") -> 21410 | Q28: CDCLSA04 | R28: 1340 | T28: CDCLSA05 | U28: 2640 | W28: CDCLSA03 | X28: 40 | Z28: CDCLSA05 | AA28: 670 | AC28: CDSPSA23 | AD28: 7762
A29: The Select Aisle Corn Flour | B29: BIFISA10 | C29: 25095.441 | D29: 25095.441 | E29: 1248.5805 | F29: 1843.6818 | G29: 1573.2315 | H29: 2512.9932 | I29: =IFERROR(VLOOKUP($B29,$Q$2:$R$81,2,FALSE),"-") -> 23189 | J29: =IFERROR(VLOOKUP($B29,$T$2:$U$81,2,FALSE),"-") -> 51176 | K29: =IFERROR(VLOOKUP($B29,$W$2:$X$81,2,FALSE),"-") -> 85650 | L29: =IFERROR(VLOOKUP($B29,$Z$2:$AA$81,2,FALSE),"-") -> 103693 | M29: =IFERROR(VLOOKUP($B29,$AC$2:$AD$81,2,FALSE),"-") -> 104634 | Q29: CDCLSA05 | R29: 1020 | T29: CDCLSA06 | U29: 60 | W29: CDCLSA04 | X29: 1080 | Z29: CDCLSA06 | AA29: 40 | AC29: CDSPSA24 | AD29: 4786
A30: The Select Aisle Icing Sugar 300g | B30: BISWSA05 | C30: 1796.4571 | D30: 1796.4571 | E30: 469.35084 | F30: 630.79394 | G30: 618.93171 | H30: 325.57497 | I30: =IFERROR(VLOOKUP($B30,$Q$2:$R$81,2,FALSE),"-") -> 3758 | J30: =IFERROR(VLOOKUP($B30,$T$2:$U$81,2,FALSE),"-") -> 4142 | K30: =IFERROR(VLOOKUP($B30,$W$2:$X$81,2,FALSE),"-") -> 5144 | L30: =IFERROR(VLOOKUP($B30,$Z$2:$AA$81,2,FALSE),"-") -> 4620 | M30: =IFERROR(VLOOKUP($B30,$AC$2:$AD$81,2,FALSE),"-") -> 7722 | Q30: CDCLSA07 | R30: 100 | T30: CDCLSA07 | U30: 150 | W30: CDCLSA05 | X30: 1486 | Z30: CDSPSA23 | AA30: 12385 | AC30: CDSPSA38 | AD30: 144
